Workbook
Name clCompletado: #REF!
Name clConRetraso: #REF!
Name clEnCurso: #REF!
Name clPersonalizado1: #REF!
Name clPersonalizado2: #REF!
Name clPersonalizado4: #REF!
Name clSinComenzar: #REF!
Name S: #REF!
Name SegmentaciónDeDatos_EMPRESA: #N/A
Name txtPersonalizado1: #REF!
Name txtPersonalizado2: #REF!
Name txtPersonalizado3: #REF!
Name txtPersonalizado4: #REF!

Sheet Colaboradores
A1: Cod_colab | B1: Id | C1: Nombre | D1: Pasaporte | E1: Movil | F1: StatusSeguridad | G1: FechaAlta | H1: FechaBaja | I1: FechaInicio | J1: FechaFinPedido | K1: FechaSalidaTrabajador | L1: Contratante
A2: E1172 | B2: 1172 | C2: ABDALLAH SAMMAR | E2: +351 964 185 751 | F2: Baja | G2: 45581.917 | H2: 45645.958 | K2: 45645.958 | L2: KOTRIK INDUSTRIAL
A3: E0530 | B3: 530 | C3: ABDELFAHAM OUBOUZID | D3: 166231325 | E3: +351 927 245 833 | F3: Baja | G3: 45778.917 | K3: 45889.917 | L3: KOTRIK ROSAS
A4: E1365 | B4: 1365 | C4: ABDELHAQ GUEHOUANE | E4: 34 602 49 64 70 | F4: Baja | G4: 45438.917 | H4: 45476.917 | K4: 45456.917 | L4: KOTRIK INDUSTRIAL
A5: E1855 | B5: 1855 | C5: ABDRUBAL FONSECA RINCON | D5: BG974479 | E5: +57 311 686 4894
A6: E0663 | B6: 663 | C6: ABEL ANTONIO CUESTA CIFUENTES | E6: +39 366 142 9913 | F6: Baja | G6: 45643.958 | K6: 45666.958 | L6: KOTRIK ROSAS
A7: E0513 | B7: 513 | C7: ABRAHAM DAVID HOYOS ALVAREZ | D7: BE508253 | E7: +57 301 7613079 | F7: alta | G7: 45705.958 | L7: STOCCO
A8: E0432 | B8: 432 | C8: ADALBERTO ARAGON GOMEZ | E8: +57 310 4676699 | F8: Alta | G8: 45761.917 | L8: KOTRIK INDUSTRIAL
A9: E0687 | B9: 687 | C9: ADILSON ESCOBAR OREJUELA | D9: BE550492 | E9: +34 616 68 47 21 | F9: Baja | G9: 45760.917 | H9: 45773.917 | K9: 45773.917 | L9: KOTRIK ROSAS
A10: E1050 | B10: 1050 | C10: ADRIAN BERNAL GOMEZ | E10: +34 654 47 87 56 | F10: anulado | G10: 45553.917 | L10: KOTRIK ROSAS
A11: E0570 | B11: 570 | C11: ADRIAN CAMILO PINILLA AGUIRRE | E11: +57 311 5096970 | F11: Pendiente Alta | L11: KOTRIK INDUSTRIAL
A12: E0452 | B12: 452 | C12: ADRIAN CARLOSAMA CHAVEZ | E12: +34 604 21 21 79 | F12: pendiente alta | L12: STOCCO
A13: E1221 | B13: 1221 | C13: ADRIAN RICARDO BAQUERO GONZALEZ | E13: 57 320 4650287 | F13: Baja | G13: 45524.917 | H13: 45649.958 | K13: 45649.958 | L13: KOTRIK INDUSTRIAL
A14: E0764 | B14: 764 | C14: ADRIANO DOS SANTOS DE CARVALHO | E14: 351 910 384 813 | F14: Baja | G14: 45070.917 | K14: 45482.917 | L14: KOTRIK INDUSTRIAL
A15: E0516 | B15: 516 | C15: AGNER MARTINEZ CARREAZO | E15: +34 603 22 41 86 | F15: pendiente alta | L15: STOCCO
A16: E0814 | B16: 814 | C16: AGUINALDO JOSE DA SILVA SOUZA | D16: FR290366 | E16: 351 960 190 974 | F16: Anulado
A17: E0194 | B17: 194 | C17: ALAN FRANCISCO NAVAS DIAZ | D17: BD749809 | E17: +57 323 4616593 | F17: Alta | G17: 45760.917 | L17: KOTRIK ROSAS
A18: E0406 | B18: 406 | C18: ALAN GERSON RAMIREZ ACARO | D18: 120655378 | E18: +51 947 371 486 | F18: pendiente alta | L18: KOTRIK ROSAS
A19: E1402 | B19: 1402 | C19: ALBEIRO CARDOZO HEREDIA | D19: AY405605 | E19: +57 310 418 7853 | F19: Pendiente Alta | I19: 45804.917 | J19: 45835.917 | L19: KOTRIK ROSAS
A20: E0347 | B20: 347 | C20: ALBEIRO ENRIQUE AMOR AGUILAR | D20: AQ894821 | E20: +57 321 2579013 | F20: Pendiente Alta | G20: 45760.917 | L20: Kotrik & Rosas
A21: E0272 | B21: 272 | C21: ALBEIRO OBANDO MICOLTA | D21: BD593560 | E21: +34 637 08 87 33 | F21: Alta | G21: 45776.917 | L21: KOTRIK INDUSTRIAL
A22: E0853 | B22: 853 | C22: ALBERT IGO SILVA LIMA DE CERQUEIRA | E22: 351 926 101 401 | F22: Anulado | L22: KOTRIK INDUSTRIAL
A23: E0189 | B23: 189 | C23: ALBERTO CCENHUA MICHCA | E23: +51 956 343 384 | F23: Pendiente Alta | L23: KOTRIK INDUSTRIAL
A24: E0208 | B24: 208 | C24: ALBERTO DURAN | D24: AV989255 | E24: +48 790 797 494 | F24: Alta | G24: 45760.917 | L24: KOTRIK ROSAS
A25: E0134 | B25: 134 | C25: ALBERTO ENRIQUE MACIAS TEHERAN | E25: 57 324 5729666 | F25: Alta | G25: 45761.917 | L25: KOTRIK INDUSTRIAL
A26: E0449 | B26: 449 | C26: ALBERTO ISMAEL MENDIETA CACERES | D26: 122134064 | E26: +51 983 738 942 | F26: pendiente alta | L26: KOTRIK ROSAS
A27: E1448 | B27: 1448 | C27: ALBERTO LUIS MALDONADO BARRERA | D27: AY305422 | E27: 57 323 2914686 | F27: Pendiente Alta | L27: STOCCO
A28: E2135 | B28: 2135 | C28: ALBERTO RICHELLI DA SILVA | D28: GE293997 | E28: +351 932 828 968
A29: E1356 | B29: 1356 | C29: ALDAIR GABRIEL LARA RAMIREZ | E29: +34 611 376 106 | F29: Anulado | L29: KOTRIK ROSAS
A30: E2114 | B30: 2114 | C30: ALDEMAR DOMINGUEZ CERCADO | D30: BG720416 | E30: +34 604 10 75 05
A31: E0460 | B31: 460 | C31: ALDO IVAN AILIO LABBE | D31: AAI878342 | E31: +54 911 265 34702 | F31: Pendiente Alta | L31: KOTRIK INDUSTRIAL
A32: E1382 | B32: 1382 | C32: ALDO LUIS CHACON BALAREZO | D32: 223302581 | E32: +51 915 332 957 | F32: Baja | K32: 45719.958 | L32: KOTRIK ROSAS
A33: E1449 | B33: 1449 | C33: ALDRINIS EDWARDS MENDOZA NIETO | E33: +57 301 782 4463 | F33: Pendiente Alta | L33: STOCCO
A34: E0648 | B34: 648 | C34: ALDRUMAR CABALLERO MARTINEZ | D34: AT606726 | E34: +57 316 299 0121 | F34: Baja | K34: 45781.917 | L34: KOTRIK ROSAS
A35: E0243 | B35: 243 | C35: ALEEX IVAN LOPEZ CUBILLOS | D35: BE054818 | E35: +34 641 56 11 84 | F35: Alta | G35: 45761.917 | L35: KOTRIK INDUSTRIAL
A36: E1770 | B36: 1770 | C36: ALEJANDRO ERWIN ZAMBRANO AGUILERA | D36: P13933983 | E36: +46 767 098 768 | F36: Pendiente Alta | L36: WISEOWE, UNIPESSOAL LDA
A37: E0662 | B37: 662 | C37: ALEJANDRO GONZALO URIBE | E37: +57 320 7160004 | F37: Baja | G37: 45536.917 | H37: 45555.917 | K37: 45555.917 | L37: KOTRIK ROSAS
A38: E0009 | B38: 9 | C38: ALEJANDRO HERNANDEZ PIMIENTA | D38: AS996395 | E38: +57 313 7806680 | F38: Alta | G38: 45784.917 | K38: 45804.917 | L38: KOTRIK INDUSTRIAL
A39: E0128 | B39: 128 | C39: ALEJANDRO JOSE BORJA MANGA | E39: +34647527268 | F39: Alta | G39: 45784.917 | H39: 45747.917 | L39: KOTRIK INDUSTRIAL
A40: E0960 | B40: 960 | C40: ALEJANDRO QUINCENO ROA | E40: 34 674 42 17 82 | F40: Baja | G40: 45470.917 | H40: 45566.917 | K40: 45566.917 | L40: KOTRIK ROSAS
...

Sheet Analises
W6: Janeiro | X6: Fevereiro | Y6: Março | Z6: Abril | AA6: Maio | AB6: Junho | AC6: Julho | AD6: Agosto
V7: Wiseowe | AA7: 18720.63 | AB7: 43132.986 | AC7: 47111.644 | AD7: 130651.03
V8: Kotrik Industrial | AA8: 877075.91 | AB8: 836098.04 | AC8: 614968.95 | AD8: 458754.58
V9: Kotrik Rosas | AA9: 673295.74 | AB9: 554018.72 | AC9: 532254.25 | AD9: 404359.84

Sheet Declaração salário
D1: VENCIMENTOS JANEIRO
B2: EMPRESA | C2: COD | D2: TRABALHADOR | E2: INICIO VINCULO | F2: FIM VINCULO | G2: HORAS TRABALHADAS | H2: TARIFA | I2: ALOJAMENTO | J2: DIAS DE ALTA | K2: IMPOSTO | L2: CARRO | M2: OUTROS DEScontos | N2: VALOR | O2: SALDO PENDENTE | P2: Columna1
B3: KR | C3: =IF(D3="", "", INDEX(Colaboradores!A:A, MATCH(D3,Colaboradores!C:C, 0))) -> E0194 | D3: ALAN FRANCISCO NAVAS DIAZ | E3: 45761 | F3: 46053 | G3: =IFERROR(VLOOKUP(Tabla10[[#This Row],[COD]],'TotalHorasAjustadas (2)'!D:L,8,FALSE),"") -> 144 | H3: =IFERROR(VLOOKUP(Tabla10[[#This Row],[COD]],Tabla15[],4,FALSE),"") -> 13 | I3: =IFERROR(VLOOKUP(Tabla10[[#This Row],[COD]],Alojamentos!B:P,11,FALSE),"") -> 300 | J3: =IF(ISBLANK(Tabla10[[#This Row],[INICIO VINCULO]]), 0, MAX(0, MIN(IF(ISBLANK(Tabla10[[#This Row],[FIM VINCULO]]), DATE(2026,1,31), Tabla10[[#This Row],[FIM VINCULO]]), DATE(2026,1,31)) - MAX(Tabla10[[#This Row],[INICIO VINCULO]], DATE(2026,1,1)) + 1)) -> 31 | K3: =7.05806*Tabla10[[#This Row],[DIAS DE ALTA]] -> 218.79986 | L3: =IFERROR(VLOOKUP(Tabla10[[#This Row],[COD]],Carro!B:D,3,FALSE),"") | M3: =IFERROR(VLOOKUP(Tabla10[[#This Row],[COD]],'Outros descontos'!B:P,15,FALSE),"") | N3: =(Tabla10[[#This Row],[HORAS TRABALHADAS]]*Tabla10[[#This Row],[TARIFA]]) - SUM(Tabla10[[#This Row],[ALOJAMENTO]], Tabla10[[#This Row],[IMPOSTO]], Tabla10[[#This Row],[CARRO]]) -> 1353.2001
B4: WS | C4: =IF(D4="", "", INDEX(Colaboradores!A:A, MATCH(D4,Colaboradores!C:C, 0))) -> E0272 | D4: ALBEIRO OBANDO MICOLTA | E4: 45945 | G4: =IFERROR(VLOOKUP(Tabla10[[#This Row],[COD]],'TotalHorasAjustadas (2)'!D:L,8,FALSE),"") -> 179 | H4: =IFERROR(VLOOKUP(Tabla10[[#This Row],[COD]],Tabla15[],4,FALSE),"") -> 17 | I4: =IFERROR(VLOOKUP(Tabla10[[#This Row],[COD]],Alojamentos!B:P,11,FALSE),"") -> 300 | J4: =IF(ISBLANK(Tabla10[[#This Row],[INICIO VINCULO]]), 0, MAX(0, MIN(IF(ISBLANK(Tabla10[[#This Row],[FIM VINCULO]]), DATE(2026,1,31), Tabla10[[#This Row],[FIM VINCULO]]), DATE(2026,1,31)) - MAX(Tabla10[[#This Row],[INICIO VINCULO]], DATE(2026,1,1)) + 1)) -> 31 | K4: =7.05806*Tabla10[[#This Row],[DIAS DE ALTA]] -> 218.79986 | L4: =IFERROR(VLOOKUP(Tabla10[[#This Row],[COD]],Carro!B:D,3,FALSE),"") | M4: =IFERROR(VLOOKUP(Tabla10[[#This Row],[COD]],'Outros descontos'!B:P,15,FALSE),"") | N4: =(Tabla10[[#This Row],[HORAS TRABALHADAS]]*Tabla10[[#This Row],[TARIFA]]) - SUM(Tabla10[[#This Row],[ALOJAMENTO]], Tabla10[[#This Row],[IMPOSTO]], Tabla10[[#This Row],[CARRO]]) -> 2524.2001
B5: KI | C5: =IF(D5="", "", INDEX(Colaboradores!A:A, MATCH(D5,Colaboradores!C:C, 0))) -> E0388 | D5: ALEX DAVID GOMEZ VILLADA | E5: 45762 | F5: 46052 | G5: =IFERROR(VLOOKUP(Tabla10[[#This Row],[COD]],'TotalHorasAjustadas (2)'!D:L,8,FALSE),"") -> 181 | H5: =IFERROR(VLOOKUP(Tabla10[[#This Row],[COD]],Tabla15[],4,FALSE),"") -> 15 | I5: =IFERROR(VLOOKUP(Tabla10[[#This Row],[COD]],Alojamentos!B:P,11,FALSE),"") | J5: =IF(ISBLANK(Tabla10[[#This Row],[INICIO VINCULO]]), 0, MAX(0, MIN(IF(ISBLANK(Tabla10[[#This Row],[FIM VINCULO]]), DATE(2026,1,31), Tabla10[[#This Row],[FIM VINCULO]]), DATE(2026,1,31)) - MAX(Tabla10[[#This Row],[INICIO VINCULO]], DATE(2026,1,1)) + 1)) -> 30 | K5: =7.05806*Tabla10[[#This Row],[DIAS DE ALTA]] -> 211.7418 | L5: =IFERROR(VLOOKUP(Tabla10[[#This Row],[COD]],Carro!B:D,3,FALSE),"") | M5: =IFERROR(VLOOKUP(Tabla10[[#This Row],[COD]],'Outros descontos'!B:P,15,FALSE),"") | N5: =(Tabla10[[#This Row],[HORAS TRABALHADAS]]*Tabla10[[#This Row],[TARIFA]]) - SUM(Tabla10[[#This Row],[ALOJAMENTO]], Tabla10[[#This Row],[IMPOSTO]], Tabla10[[#This Row],[CARRO]]) -> 2503.2582
B6: LM | C6: =IF(D6="", "", INDEX(Colaboradores!A:A, MATCH(D6,Colaboradores!C:C, 0))) -> E2098 | D6: ALEXANDER GUZMAN | E6: 46051 | G6: =IFERROR(VLOOKUP(Tabla10[[#This Row],[COD]],'TotalHorasAjustadas (2)'!D:L,8,FALSE),"") -> 23 | H6: 15 | I6: =IFERROR(VLOOKUP(Tabla10[[#This Row],[COD]],Alojamentos!B:P,11,FALSE),"") | J6: =IF(ISBLANK(Tabla10[[#This Row],[INICIO VINCULO]]), 0, MAX(0, MIN(IF(ISBLANK(Tabla10[[#This Row],[FIM VINCULO]]), DATE(2026,1,31), Tabla10[[#This Row],[FIM VINCULO]]), DATE(2026,1,31)) - MAX(Tabla10[[#This Row],[INICIO VINCULO]], DATE(2026,1,1)) + 1)) -> 3 | K6: =7.05806*Tabla10[[#This Row],[DIAS DE ALTA]] -> 21.17418 | L6: =IFERROR(VLOOKUP(Tabla10[[#This Row],[COD]],Carro!B:D,3,FALSE),"") -> 10 | M6: =IFERROR(VLOOKUP(Tabla10[[#This Row],[COD]],'Outros descontos'!B:P,15,FALSE),"") | N6: =(Tabla10[[#This Row],[HORAS TRABALHADAS]]*Tabla10[[#This Row],[TARIFA]]) - SUM(Tabla10[[#This Row],[ALOJAMENTO]], Tabla10[[#This Row],[IMPOSTO]], Tabla10[[#This Row],[CARRO]]) -> 313.82582
B7: WS | C7: =IF(D7="", "", INDEX(Colaboradores!A:A, MATCH(D7,Colaboradores!C:C, 0))) -> E0386 | D7: ALEXANDER MANUEL LOPEZ ROJAS | E7: 45939 | G7: =IFERROR(VLOOKUP(Tabla10[[#This Row],[COD]],'TotalHorasAjustadas (2)'!D:L,8,FALSE),"") -> 188.5 | H7: =IFERROR(VLOOKUP(Tabla10[[#This Row],[COD]],Tabla15[],4,FALSE),"") -> 12 | I7: =IFERROR(VLOOKUP(Tabla10[[#This Row],[COD]],Alojamentos!B:P,11,FALSE),"") | J7: =IF(ISBLANK(Tabla10[[#This Row],[INICIO VINCULO]]), 0, MAX(0, MIN(IF(ISBLANK(Tabla10[[#This Row],[FIM VINCULO]]), DATE(2026,1,31), Tabla10[[#This Row],[FIM VINCULO]]), DATE(2026,1,31)) - MAX(Tabla10[[#This Row],[INICIO VINCULO]], DATE(2026,1,1)) + 1)) -> 31 | K7: =7.05806*Tabla10[[#This Row],[DIAS DE ALTA]] -> 218.79986 | L7: =IFERROR(VLOOKUP(Tabla10[[#This Row],[COD]],Carro!B:D,3,FALSE),"") | M7: =IFERROR(VLOOKUP(Tabla10[[#This Row],[COD]],'Outros descontos'!B:P,15,FALSE),"") | N7: =(Tabla10[[#This Row],[HORAS TRABALHADAS]]*Tabla10[[#This Row],[TARIFA]]) - SUM(Tabla10[[#This Row],[ALOJAMENTO]], Tabla10[[#This Row],[IMPOSTO]], Tabla10[[#This Row],[CARRO]]) -> 2043.2001
B8: LM | C8: =IF(D8="", "", INDEX(Colaboradores!A:A, MATCH(D8,Colaboradores!C:C, 0))) -> E0254 | D8: ALIRIO ORTIZ MOLINA | E8: 46030 | G8: =IFERROR(VLOOKUP(Tabla10[[#This Row],[COD]],'TotalHorasAjustadas (2)'!D:L,8,FALSE),"") -> 171 | H8: 15 | I8: =IFERROR(VLOOKUP(Tabla10[[#This Row],[COD]],Alojamentos!B:P,11,FALSE),"") -> 240 | J8: =IF(ISBLANK(Tabla10[[#This Row],[INICIO VINCULO]]), 0, MAX(0, MIN(IF(ISBLANK(Tabla10[[#This Row],[FIM VINCULO]]), DATE(2026,1,31), Tabla10[[#This Row],[FIM VINCULO]]), DATE(2026,1,31)) - MAX(Tabla10[[#This Row],[INICIO VINCULO]], DATE(2026,1,1)) + 1)) -> 24 | K8: =7.05806*Tabla10[[#This Row],[DIAS DE ALTA]] -> 169.39344 | L8: =IFERROR(VLOOKUP(Tabla10[[#This Row],[COD]],Carro!B:D,3,FALSE),"") | M8: =IFERROR(VLOOKUP(Tabla10[[#This Row],[COD]],'Outros descontos'!B:P,15,FALSE),"") | N8: =(Tabla10[[#This Row],[HORAS TRABALHADAS]]*Tabla10[[#This Row],[TARIFA]]) - SUM(Tabla10[[#This Row],[ALOJAMENTO]], Tabla10[[#This Row],[IMPOSTO]], Tabla10[[#This Row],[CARRO]]) -> 2155.6066
B9: KI | C9: =IF(D9="", "", INDEX(Colaboradores!A:A, MATCH(D9,Colaboradores!C:C, 0))) -> E0166 | D9: ALVARO ENRIQUE ROJAS DE LA OSSA | E9: 45762 | F9: 46053 | G9: =IFERROR(VLOOKUP(Tabla10[[#This Row],[COD]],'TotalHorasAjustadas (2)'!D:L,8,FALSE),"") -> 144 | H9: =IFERROR(VLOOKUP(Tabla10[[#This Row],[COD]],Tabla15[],4,FALSE),"") -> 17 | I9: =IFERROR(VLOOKUP(Tabla10[[#This Row],[COD]],Alojamentos!B:P,11,FALSE),"") | J9: =IF(ISBLANK(Tabla10[[#This Row],[INICIO VINCULO]]), 0, MAX(0, MIN(IF(ISBLANK(Tabla10[[#This Row],[FIM VINCULO]]), DATE(2026,1,31), Tabla10[[#This Row],[FIM VINCULO]]), DATE(2026,1,31)) - MAX(Tabla10[[#This Row],[INICIO VINCULO]], DATE(2026,1,1)) + 1)) -> 31 | K9: =7.05806*Tabla10[[#This Row],[DIAS DE ALTA]] -> 218.79986 | L9: =IFERROR(VLOOKUP(Tabla10[[#This Row],[COD]],Carro!B:D,3,FALSE),"") | M9: =IFERROR(VLOOKUP(Tabla10[[#This Row],[COD]],'Outros descontos'!B:P,15,FALSE),"") | N9: =(Tabla10[[#This Row],[HORAS TRABALHADAS]]*Tabla10[[#This Row],[TARIFA]]) - SUM(Tabla10[[#This Row],[ALOJAMENTO]], Tabla10[[#This Row],[IMPOSTO]], Tabla10[[#This Row],[CARRO]]) -> 2229.2001
B10: KR | C10: =IF(D10="", "", INDEX(Colaboradores!A:A, MATCH(D10,Colaboradores!C:C, 0))) -> E2079 | D10: ALVARO JAVIER NARVAEZ MUÑOZ | E10: 45827 | F10: 46052 | G10: =IFERROR(VLOOKUP(Tabla10[[#This Row],[COD]],'TotalHorasAjustadas (2)'!D:L,8,FALSE),"") -> 144 | H10: 15 | I10: =IFERROR(VLOOKUP(Tabla10[[#This Row],[COD]],Alojamentos!B:P,11,FALSE),"") -> 300 | J10: =IF(ISBLANK(Tabla10[[#This Row],[INICIO VINCULO]]), 0, MAX(0, MIN(IF(ISBLANK(Tabla10[[#This Row],[FIM VINCULO]]), DATE(2026,1,31), Tabla10[[#This Row],[FIM VINCULO]]), DATE(2026,1,31)) - MAX(Tabla10[[#This Row],[INICIO VINCULO]], DATE(2026,1,1)) + 1)) -> 30 | K10: =7.05806*Tabla10[[#This Row],[DIAS DE ALTA]] -> 211.7418 | L10: =IFERROR(VLOOKUP(Tabla10[[#This Row],[COD]],Carro!B:D,3,FALSE),"") | M10: =IFERROR(VLOOKUP(Tabla10[[#This Row],[COD]],'Outros descontos'!B:P,15,FALSE),"") | N10: =(Tabla10[[#This Row],[HORAS TRABALHADAS]]*Tabla10[[#This Row],[TARIFA]]) - SUM(Tabla10[[#This Row],[ALOJAMENTO]], Tabla10[[#This Row],[IMPOSTO]], Tabla10[[#This Row],[CARRO]]) -> 1648.2582
B11: WS | D11: ANA LUIZA TAVARES LARA | E11: 45819 | G11: 160 | H11: 0 | I11: =IFERROR(VLOOKUP(Tabla10[[#This Row],[COD]],Alojamentos!B:P,11,FALSE),"") | J11: =IF(ISBLANK(Tabla10[[#This Row],[INICIO VINCULO]]), 0, MAX(0, MIN(IF(ISBLANK(Tabla10[[#This Row],[FIM VINCULO]]), DATE(2026,1,31), Tabla10[[#This Row],[FIM VINCULO]]), DATE(2026,1,31)) - MAX(Tabla10[[#This Row],[INICIO VINCULO]], DATE(2026,1,1)) + 1)) -> 31 | K11: 0 | L11: =IFERROR(VLOOKUP(Tabla10[[#This Row],[COD]],Carro!B:D,3,FALSE),"") | M11: =IFERROR(VLOOKUP(Tabla10[[#This Row],[COD]],'Outros descontos'!B:P,15,FALSE),"") | N11: 1528.13
B12: WS | C12: =IF(D12="", "", INDEX(Colaboradores!A:A, MATCH(D12,Colaboradores!C:C, 0))) -> E0500 | D12: ANDRES CAMILO ALVAREZ CUERVO | E12: 45896 | G12: 208.5 | H12: =IFERROR(VLOOKUP(Tabla10[[#This Row],[COD]],Tabla15[],4,FALSE),"") -> 15 | I12: =IFERROR(VLOOKUP(Tabla10[[#This Row],[COD]],Alojamentos!B:P,11,FALSE),"") | J12: =IF(ISBLANK(Tabla10[[#This Row],[INICIO VINCULO]]), 0, MAX(0, MIN(IF(ISBLANK(Tabla10[[#This Row],[FIM VINCULO]]), DATE(2026,1,31), Tabla10[[#This Row],[FIM VINCULO]]), DATE(2026,1,31)) - MAX(Tabla10[[#This Row],[INICIO VINCULO]], DATE(2026,1,1)) + 1)) -> 31 | K12: =7.05806*Tabla10[[#This Row],[DIAS DE ALTA]] -> 218.79986 | L12: =IFERROR(VLOOKUP(Tabla10[[#This Row],[COD]],Carro!B:D,3,FALSE),"") -> 140 | M12: =IFERROR(VLOOKUP(Tabla10[[#This Row],[COD]],'Outros descontos'!B:P,15,FALSE),"") | N12: =(Tabla10[[#This Row],[HORAS TRABALHADAS]]*Tabla10[[#This Row],[TARIFA]]) - SUM(Tabla10[[#This Row],[ALOJAMENTO]], Tabla10[[#This Row],[IMPOSTO]], Tabla10[[#This Row],[CARRO]]) -> 2768.7001
B13: KR | C13: =IF(D13="", "", INDEX(Colaboradores!A:A, MATCH(D13,Colaboradores!C:C, 0))) -> E0359 | D13: ANDRES FELIPE GOMEZ PUERTA | E13: 45852 | F13: 46052 | G13: =IFERROR(VLOOKUP(Tabla10[[#This Row],[COD]],'TotalHorasAjustadas (2)'!D:L,8,FALSE),"") -> 133 | H13: =IFERROR(VLOOKUP(Tabla10[[#This Row],[COD]],Tabla15[],4,FALSE),"") -> 15 | I13: =IFERROR(VLOOKUP(Tabla10[[#This Row],[COD]],Alojamentos!B:P,11,FALSE),"") -> 300 | J13: =IF(ISBLANK(Tabla10[[#This Row],[INICIO VINCULO]]), 0, MAX(0, MIN(IF(ISBLANK(Tabla10[[#This Row],[FIM VINCULO]]), DATE(2026,1,31), Tabla10[[#This Row],[FIM VINCULO]]), DATE(2026,1,31)) - MAX(Tabla10[[#This Row],[INICIO VINCULO]], DATE(2026,1,1)) + 1)) -> 30 | K13: =7.05806*Tabla10[[#This Row],[DIAS DE ALTA]] -> 211.7418 | L13: =IFERROR(VLOOKUP(Tabla10[[#This Row],[COD]],Carro!B:D,3,FALSE),"") | M13: =IFERROR(VLOOKUP(Tabla10[[#This Row],[COD]],'Outros descontos'!B:P,15,FALSE),"") | N13: =(Tabla10[[#This Row],[HORAS TRABALHADAS]]*Tabla10[[#This Row],[TARIFA]]) - SUM(Tabla10[[#This Row],[ALOJAMENTO]], Tabla10[[#This Row],[IMPOSTO]], Tabla10[[#This Row],[CARRO]]) -> 1483.2582
B14: WS | C14: =IF(D14="", "", INDEX(Colaboradores!A:A, MATCH(D14,Colaboradores!C:C, 0))) -> E0617 | D14: ANDRES FELIPE MARULANDA ARAQUE | E14: 45945 | G14: =IFERROR(VLOOKUP(Tabla10[[#This Row],[COD]],'TotalHorasAjustadas (2)'!D:L,8,FALSE),"") -> 268 | H14: =IFERROR(VLOOKUP(Tabla10[[#This Row],[COD]],Tabla15[],4,FALSE),"") -> 15 | I14: =IFERROR(VLOOKUP(Tabla10[[#This Row],[COD]],Alojamentos!B:P,11,FALSE),"") | J14: =IF(ISBLANK(Tabla10[[#This Row],[INICIO VINCULO]]), 0, MAX(0, MIN(IF(ISBLANK(Tabla10[[#This Row],[FIM VINCULO]]), DATE(2026,1,31), Tabla10[[#This Row],[FIM VINCULO]]), DATE(2026,1,31)) - MAX(Tabla10[[#This Row],[INICIO VINCULO]], DATE(2026,1,1)) + 1)) -> 31 | K14: =7.05806*Tabla10[[#This Row],[DIAS DE ALTA]] -> 218.79986 | L14: =IFERROR(VLOOKUP(Tabla10[[#This Row],[COD]],Carro!B:D,3,FALSE),"") -> 66.666667 | M14: =IFERROR(VLOOKUP(Tabla10[[#This Row],[COD]],'Outros descontos'!B:P,15,FALSE),"") -> 148.97 | N14: =(Tabla10[[#This Row],[HORAS TRABALHADAS]]*Tabla10[[#This Row],[TARIFA]]) - SUM(Tabla10[[#This Row],[ALOJAMENTO]], Tabla10[[#This Row],[IMPOSTO]], Tabla10[[#This Row],[CARRO]],Tabla10[[#This Row],[OUTROS DEScontos]]) -> 3585.5635
B15: KR | C15: =IF(D15="", "", INDEX(Colaboradores!A:A, MATCH(D15,Colaboradores!C:C, 0))) -> E0195 | D15: BLADIMIRO DIAZ MARTINEZ | E15: 45761 | F15: 46053 | G15: =IFERROR(VLOOKUP(Tabla10[[#This Row],[COD]],'TotalHorasAjustadas (2)'!D:L,8,FALSE),"") -> 144 | H15: =IFERROR(VLOOKUP(Tabla10[[#This Row],[COD]],Tabla15[],4,FALSE),"") -> 13 | I15: =IFERROR(VLOOKUP(Tabla10[[#This Row],[COD]],Alojamentos!B:P,11,FALSE),"") -> 300 | J15: =IF(ISBLANK(Tabla10[[#This Row],[INICIO VINCULO]]), 0, MAX(0, MIN(IF(ISBLANK(Tabla10[[#This Row],[FIM VINCULO]]), DATE(2026,1,31), Tabla10[[#This Row],[FIM VINCULO]]), DATE(2026,1,31)) - MAX(Tabla10[[#This Row],[INICIO VINCULO]], DATE(2026,1,1)) + 1)) -> 31 | K15: =7.05806*Tabla10[[#This Row],[DIAS DE ALTA]] -> 218.79986 | L15: =IFERROR(VLOOKUP(Tabla10[[#This Row],[COD]],Carro!B:D,3,FALSE),"") | M15: =IFERROR(VLOOKUP(Tabla10[[#This Row],[COD]],'Outros descontos'!B:P,15,FALSE),"") | N15: =(Tabla10[[#This Row],[HORAS TRABALHADAS]]*Tabla10[[#This Row],[TARIFA]]) - SUM(Tabla10[[#This Row],[ALOJAMENTO]], Tabla10[[#This Row],[IMPOSTO]], Tabla10[[#This Row],[CARRO]]) -> 1353.2001
B16: WS | C16: =IF(D16="", "", INDEX(Colaboradores!A:A, MATCH(D16,Colaboradores!C:C, 0))) -> E1668 | D16: BRAYAN JOSE SALINAS MARTINEZ | E16: 45945 | G16: 165 | H16: =IFERROR(VLOOKUP(Tabla10[[#This Row],[COD]],Tabla15[],4,FALSE),"") -> 15 | I16: =IFERROR(VLOOKUP(Tabla10[[#This Row],[COD]],Alojamentos!B:P,11,FALSE),"") | J16: =IF(ISBLANK(Tabla10[[#This Row],[INICIO VINCULO]]), 0, MAX(0, MIN(IF(ISBLANK(Tabla10[[#This Row],[FIM VINCULO]]), DATE(2026,1,31), Tabla10[[#This Row],[FIM VINCULO]]), DATE(2026,1,31)) - MAX(Tabla10[[#This Row],[INICIO VINCULO]], DATE(2026,1,1)) + 1)) -> 31 | K16: =7.05806*Tabla10[[#This Row],[DIAS DE ALTA]] -> 218.79986 | L16: =IFERROR(VLOOKUP(Tabla10[[#This Row],[COD]],Carro!B:D,3,FALSE),"") | M16: =IFERROR(VLOOKUP(Tabla10[[#This Row],[COD]],'Outros descontos'!B:P,15,FALSE),"") | N16: =(Tabla10[[#This Row],[HORAS TRABALHADAS]]*Tabla10[[#This Row],[TARIFA]]) - SUM(Tabla10[[#This Row],[ALOJAMENTO]], Tabla10[[#This Row],[IMPOSTO]], Tabla10[[#This Row],[CARRO]]) -> 2256.2001
B17: KR | C17: =IF(D17="", "", INDEX(Colaboradores!A:A, MATCH(D17,Colaboradores!C:C, 0))) -> E0558 | D17: BREIDIS JOSE CARDOZO GALUE | E17: 45761 | G17: =IFERROR(VLOOKUP(Tabla10[[#This Row],[COD]],'TotalHorasAjustadas (2)'!D:L,8,FALSE),"") -> 194 | H17: =IFERROR(VLOOKUP(Tabla10[[#This Row],[COD]],Tabla15[],4,FALSE),"") -> 15 | I17: =IFERROR(VLOOKUP(Tabla10[[#This Row],[COD]],Alojamentos!B:P,11,FALSE),"") | J17: =IF(ISBLANK(Tabla10[[#This Row],[INICIO VINCULO]]), 0, MAX(0, MIN(IF(ISBLANK(Tabla10[[#This Row],[FIM VINCULO]]), DATE(2026,1,31), Tabla10[[#This Row],[FIM VINCULO]]), DATE(2026,1,31)) - MAX(Tabla10[[#This Row],[INICIO VINCULO]], DATE(2026,1,1)) + 1)) -> 31 | K17: =7.05806*Tabla10[[#This Row],[DIAS DE ALTA]] -> 218.79986 | L17: =IFERROR(VLOOKUP(Tabla10[[#This Row],[COD]],Carro!B:D,3,FALSE),"") | M17: =IFERROR(VLOOKUP(Tabla10[[#This Row],[COD]],'Outros descontos'!B:P,15,FALSE),"") | N17: =(Tabla10[[#This Row],[HORAS TRABALHADAS]]*Tabla10[[#This Row],[TARIFA]]) - SUM(Tabla10[[#This Row],[ALOJAMENTO]], Tabla10[[#This Row],[IMPOSTO]], Tabla10[[#This Row],[CARRO]]) -> 2691.2001
B18: LM | C18: =IF(D18="", "", INDEX(Colaboradores!A:A, MATCH(D18,Colaboradores!C:C, 0))) -> E0622 | D18: BREINER MOLINA PELAEZ | E18: 45942 | G18: =IFERROR(VLOOKUP(Tabla10[[#This Row],[COD]],'TotalHorasAjustadas (2)'!D:L,8,FALSE),"") -> 210 | H18: =IFERROR(VLOOKUP(Tabla10[[#This Row],[COD]],Tabla15[],4,FALSE),"") -> 15 | I18: =IFERROR(VLOOKUP(Tabla10[[#This Row],[COD]],Alojamentos!B:P,11,FALSE),"") | J18: =IF(ISBLANK(Tabla10[[#This Row],[INICIO VINCULO]]), 0, MAX(0, MIN(IF(ISBLANK(Tabla10[[#This Row],[FIM VINCULO]]), DATE(2026,1,31), Tabla10[[#This Row],[FIM VINCULO]]), DATE(2026,1,31)) - MAX(Tabla10[[#This Row],[INICIO VINCULO]], DATE(2026,1,1)) + 1)) -> 31 | K18: =7.05806*Tabla10[[#This Row],[DIAS DE ALTA]] -> 218.79986 | L18: =IFERROR(VLOOKUP(Tabla10[[#This Row],[COD]],Carro!B:D,3,FALSE),"") -> 102.66 | M18: =IFERROR(VLOOKUP(Tabla10[[#This Row],[COD]],'Outros descontos'!B:P,15,FALSE),"") -> 53.16 | N18: =(Tabla10[[#This Row],[HORAS TRABALHADAS]]*Tabla10[[#This Row],[TARIFA]]) - SUM(Tabla10[[#This Row],[ALOJAMENTO]], Tabla10[[#This Row],[IMPOSTO]], Tabla10[[#This Row],[CARRO]],Tabla10[[#This Row],[OUTROS DEScontos]]) -> 2775.3801
B19: WS | D19: BRENDA JAVORSKI NECKEL | E19: 45819 | G19: 160 | H19: 0 | I19: =IFERROR(VLOOKUP(Tabla10[[#This Row],[COD]],Alojamentos!B:P,11,FALSE),"") | J19: =IF(ISBLANK(Tabla10[[#This Row],[INICIO VINCULO]]), 0, MAX(0, MIN(IF(ISBLANK(Tabla10[[#This Row],[FIM VINCULO]]), DATE(2026,1,31), Tabla10[[#This Row],[FIM VINCULO]]), DATE(2026,1,31)) - MAX(Tabla10[[#This Row],[INICIO VINCULO]], DATE(2026,1,1)) + 1)) -> 31 | K19: 0 | L19: =IFERROR(VLOOKUP(Tabla10[[#This Row],[COD]],Carro!B:D,3,FALSE),"") | M19: =IFERROR(VLOOKUP(Tabla10[[#This Row],[COD]],'Outros descontos'!B:P,15,FALSE),"") | N19: 2337.5
B20: KI | C20: =IF(D20="", "", INDEX(Colaboradores!A:A, MATCH(D20,Colaboradores!C:C, 0))) -> E0277 | D20: CAMILO ANDRES VALERO PEREZ | E20: 45762 | F20: 46053 | G20: =IFERROR(VLOOKUP(Tabla10[[#This Row],[COD]],'TotalHorasAjustadas (2)'!D:L,8,FALSE),"") -> 201 | H20: =IFERROR(VLOOKUP(Tabla10[[#This Row],[COD]],Tabla15[],4,FALSE),"") -> 15 | I20: =IFERROR(VLOOKUP(Tabla10[[#This Row],[COD]],Alojamentos!B:P,11,FALSE),"") | J20: =IF(ISBLANK(Tabla10[[#This Row],[INICIO VINCULO]]), 0, MAX(0, MIN(IF(ISBLANK(Tabla10[[#This Row],[FIM VINCULO]]), DATE(2026,1,31), Tabla10[[#This Row],[FIM VINCULO]]), DATE(2026,1,31)) - MAX(Tabla10[[#This Row],[INICIO VINCULO]], DATE(2026,1,1)) + 1)) -> 31 | K20: =7.05806*Tabla10[[#This Row],[DIAS DE ALTA]] -> 218.79986 | L20: =IFERROR(VLOOKUP(Tabla10[[#This Row],[COD]],Carro!B:D,3,FALSE),"") -> 145 | M20: =IFERROR(VLOOKUP(Tabla10[[#This Row],[COD]],'Outros descontos'!B:P,15,FALSE),"") | N20: =(Tabla10[[#This Row],[HORAS TRABALHADAS]]*Tabla10[[#This Row],[TARIFA]]) - SUM(Tabla10[[#This Row],[ALOJAMENTO]], Tabla10[[#This Row],[IMPOSTO]], Tabla10[[#This Row],[CARRO]]) -> 2651.2001
B21: KR | C21: =IF(D21="", "", INDEX(Colaboradores!A:A, MATCH(D21,Colaboradores!C:C, 0))) -> E0396 | D21: CARLOS ANDRES JIMENEZ RAMIREZ | E21: 45880 | F21: 46052 | G21: =IFERROR(VLOOKUP(Tabla10[[#This Row],[COD]],'TotalHorasAjustadas (2)'!D:L,8,FALSE),"") -> 143 | H21: =IFERROR(VLOOKUP(Tabla10[[#This Row],[COD]],Tabla15[],4,FALSE),"") -> 15 | I21: =IFERROR(VLOOKUP(Tabla10[[#This Row],[COD]],Alojamentos!B:P,11,FALSE),"") -> 300 | J21: =IF(ISBLANK(Tabla10[[#This Row],[INICIO VINCULO]]), 0, MAX(0, MIN(IF(ISBLANK(Tabla10[[#This Row],[FIM VINCULO]]), DATE(2026,1,31), Tabla10[[#This Row],[FIM VINCULO]]), DATE(2026,1,31)) - MAX(Tabla10[[#This Row],[INICIO VINCULO]], DATE(2026,1,1)) + 1)) -> 30 | K21: =7.05806*Tabla10[[#This Row],[DIAS DE ALTA]] -> 211.7418 | L21: =IFERROR(VLOOKUP(Tabla10[[#This Row],[COD]],Carro!B:D,3,FALSE),"") | M21: =IFERROR(VLOOKUP(Tabla10[[#This Row],[COD]],'Outros descontos'!B:P,15,FALSE),"") | N21: =(Tabla10[[#This Row],[HORAS TRABALHADAS]]*Tabla10[[#This Row],[TARIFA]]) - SUM(Tabla10[[#This Row],[ALOJAMENTO]], Tabla10[[#This Row],[IMPOSTO]], Tabla10[[#This Row],[CARRO]]) -> 1633.2582
B22: LM | C22: =IF(D22="", "", INDEX(Colaboradores!A:A, MATCH(D22,Colaboradores!C:C, 0))) -> E1976 | D22: CARLOS DANIEL RODRIGUEZ PENA | E22: 46048 | G22: =IFERROR(VLOOKUP(Tabla10[[#This Row],[COD]],'TotalHorasAjustadas (2)'!D:L,8,FALSE),"") -> 62 | H22: 15 | I22: =IFERROR(VLOOKUP(Tabla10[[#This Row],[COD]],Alojamentos!B:P,11,FALSE),"") | J22: =IF(ISBLANK(Tabla10[[#This Row],[INICIO VINCULO]]), 0, MAX(0, MIN(IF(ISBLANK(Tabla10[[#This Row],[FIM VINCULO]]), DATE(2026,1,31), Tabla10[[#This Row],[FIM VINCULO]]), DATE(2026,1,31)) - MAX(Tabla10[[#This Row],[INICIO VINCULO]], DATE(2026,1,1)) + 1)) -> 6 | K22: =7.05806*Tabla10[[#This Row],[DIAS DE ALTA]] -> 42.34836 | L22: =IFERROR(VLOOKUP(Tabla10[[#This Row],[COD]],Carro!B:D,3,FALSE),"") -> 45 | M22: =IFERROR(VLOOKUP(Tabla10[[#This Row],[COD]],'Outros descontos'!B:P,15,FALSE),"") | N22: =(Tabla10[[#This Row],[HORAS TRABALHADAS]]*Tabla10[[#This Row],[TARIFA]]) - SUM(Tabla10[[#This Row],[ALOJAMENTO]], Tabla10[[#This Row],[IMPOSTO]], Tabla10[[#This Row],[CARRO]]) -> 842.65164
B23: LM | D23: CARLOS DE MARINS MENINO JUNIOR | E23: 45895 | G23: 160 | H23: 0 | I23: =IFERROR(VLOOKUP(Tabla10[[#This Row],[COD]],Alojamentos!B:P,11,FALSE),"") | J23: =IF(ISBLANK(Tabla10[[#This Row],[INICIO VINCULO]]), 0, MAX(0, MIN(IF(ISBLANK(Tabla10[[#This Row],[FIM VINCULO]]), DATE(2026,1,31), Tabla10[[#This Row],[FIM VINCULO]]), DATE(2026,1,31)) - MAX(Tabla10[[#This Row],[INICIO VINCULO]], DATE(2026,1,1)) + 1)) -> 31 | K23: 0 | L23: =IFERROR(VLOOKUP(Tabla10[[#This Row],[COD]],Carro!B:D,3,FALSE),"") | M23: =IFERROR(VLOOKUP(Tabla10[[#This Row],[COD]],'Outros descontos'!B:P,15,FALSE),"") | N23: 1420
B24: LM | C24: =IF(D24="", "", INDEX(Colaboradores!A:A, MATCH(D24,Colaboradores!C:C, 0))) -> E0144 | D24: CARLOS EDUARDO CARDENAS ESPINOSA | E24: 45943 | G24: =IFERROR(VLOOKUP(Tabla10[[#This Row],[COD]],'TotalHorasAjustadas (2)'!D:L,8,FALSE),"") -> 204.5 | H24: =IFERROR(VLOOKUP(Tabla10[[#This Row],[COD]],Tabla15[],4,FALSE),"") -> 15 | I24: =IFERROR(VLOOKUP(Tabla10[[#This Row],[COD]],Alojamentos!B:P,11,FALSE),"") -> 300 | J24: =IF(ISBLANK(Tabla10[[#This Row],[INICIO VINCULO]]), 0, MAX(0, MIN(IF(ISBLANK(Tabla10[[#This Row],[FIM VINCULO]]), DATE(2026,1,31), Tabla10[[#This Row],[FIM VINCULO]]), DATE(2026,1,31)) - MAX(Tabla10[[#This Row],[INICIO VINCULO]], DATE(2026,1,1)) + 1)) -> 31 | K24: =7.05806*Tabla10[[#This Row],[DIAS DE ALTA]] -> 218.79986 | L24: =IFERROR(VLOOKUP(Tabla10[[#This Row],[COD]],Carro!B:D,3,FALSE),"") | M24: =IFERROR(VLOOKUP(Tabla10[[#This Row],[COD]],'Outros descontos'!B:P,15,FALSE),"") | N24: =(Tabla10[[#This Row],[HORAS TRABALHADAS]]*Tabla10[[#This Row],[TARIFA]]) - SUM(Tabla10[[#This Row],[ALOJAMENTO]], Tabla10[[#This Row],[IMPOSTO]], Tabla10[[#This Row],[CARRO]]) -> 2548.7001
B25: KR | C25: =IF(D25="", "", INDEX(Colaboradores!A:A, MATCH(D25,Colaboradores!C:C, 0))) -> E0553 | D25: CARLOS JULIO ACOSTA CAMACHO | E25: 45779 | F25: 46052 | G25: =IFERROR(VLOOKUP(Tabla10[[#This Row],[COD]],'TotalHorasAjustadas (2)'!D:L,8,FALSE),"") -> 170 | H25: =IFERROR(VLOOKUP(Tabla10[[#This Row],[COD]],Tabla15[],4,FALSE),"") -> 15 | I25: =IFERROR(VLOOKUP(Tabla10[[#This Row],[COD]],Alojamentos!B:P,11,FALSE),"") | J25: =IF(ISBLANK(Tabla10[[#This Row],[INICIO VINCULO]]), 0, MAX(0, MIN(IF(ISBLANK(Tabla10[[#This Row],[FIM VINCULO]]), DATE(2026,1,31), Tabla10[[#This Row],[FIM VINCULO]]), DATE(2026,1,31)) - MAX(Tabla10[[#This Row],[INICIO VINCULO]], DATE(2026,1,1)) + 1)) -> 30 | K25: =7.05806*Tabla10[[#This Row],[DIAS DE ALTA]] -> 211.7418 | L25: =IFERROR(VLOOKUP(Tabla10[[#This Row],[COD]],Carro!B:D,3,FALSE),"") -> 120 | M25: =IFERROR(VLOOKUP(Tabla10[[#This Row],[COD]],'Outros descontos'!B:P,15,FALSE),"") | N25: =(Tabla10[[#This Row],[HORAS TRABALHADAS]]*Tabla10[[#This Row],[TARIFA]]) - SUM(Tabla10[[#This Row],[ALOJAMENTO]], Tabla10[[#This Row],[IMPOSTO]], Tabla10[[#This Row],[CARRO]]) -> 2218.2582
B26: WS | C26: =IF(D26="", "", INDEX(Colaboradores!A:A, MATCH(D26,Colaboradores!C:C, 0))) -> E0801 | D26: CARLOS MITCHELL SANTOS RODRIGUEZ | E26: 45945 | G26: =IFERROR(VLOOKUP(Tabla10[[#This Row],[COD]],'TotalHorasAjustadas (2)'!D:L,8,FALSE),"") -> 268 | H26: =IFERROR(VLOOKUP(Tabla10[[#This Row],[COD]],Tabla15[],4,FALSE),"") -> 15 | I26: =IFERROR(VLOOKUP(Tabla10[[#This Row],[COD]],Alojamentos!B:P,11,FALSE),"") | J26: =IF(ISBLANK(Tabla10[[#This Row],[INICIO VINCULO]]), 0, MAX(0, MIN(IF(ISBLANK(Tabla10[[#This Row],[FIM VINCULO]]), DATE(2026,1,31), Tabla10[[#This Row],[FIM VINCULO]]), DATE(2026,1,31)) - MAX(Tabla10[[#This Row],[INICIO VINCULO]], DATE(2026,1,1)) + 1)) -> 31 | K26: =7.05806*Tabla10[[#This Row],[DIAS DE ALTA]] -> 218.79986 | L26: =IFERROR(VLOOKUP(Tabla10[[#This Row],[COD]],Carro!B:D,3,FALSE),"") -> 66.666667 | M26: =IFERROR(VLOOKUP(Tabla10[[#This Row],[COD]],'Outros descontos'!B:P,15,FALSE),"") -> 148.97 | N26: =(Tabla10[[#This Row],[HORAS TRABALHADAS]]*Tabla10[[#This Row],[TARIFA]]) - SUM(Tabla10[[#This Row],[ALOJAMENTO]], Tabla10[[#This Row],[IMPOSTO]], Tabla10[[#This Row],[CARRO]],Tabla10[[#This Row],[OUTROS DEScontos]]) -> 3585.5635
B27: WS | C27: =IF(D27="", "", INDEX(Colaboradores!A:A, MATCH(D27,Colaboradores!C:C, 0))) -> E1129 | D27: CICERO LIMA BATISTA | E27: 45931 | G27: =IFERROR(VLOOKUP(Tabla10[[#This Row],[COD]],'TotalHorasAjustadas (2)'!D:L,8,FALSE),"") -> 160 | H27: =IFERROR(VLOOKUP(Tabla10[[#This Row],[COD]],Tabla15[],4,FALSE),"") -> 16 | I27: =IFERROR(VLOOKUP(Tabla10[[#This Row],[COD]],Alojamentos!B:P,11,FALSE),"") | J27: =IF(ISBLANK(Tabla10[[#This Row],[INICIO VINCULO]]), 0, MAX(0, MIN(IF(ISBLANK(Tabla10[[#This Row],[FIM VINCULO]]), DATE(2026,1,31), Tabla10[[#This Row],[FIM VINCULO]]), DATE(2026,1,31)) - MAX(Tabla10[[#This Row],[INICIO VINCULO]], DATE(2026,1,1)) + 1)) -> 31 | K27: =7.05806*Tabla10[[#This Row],[DIAS DE ALTA]] -> 218.79986 | L27: =IFERROR(VLOOKUP(Tabla10[[#This Row],[COD]],Carro!B:D,3,FALSE),"") | M27: =IFERROR(VLOOKUP(Tabla10[[#This Row],[COD]],'Outros descontos'!B:P,15,FALSE),"") | N27: =(Tabla10[[#This Row],[HORAS TRABALHADAS]]*Tabla10[[#This Row],[TARIFA]]) - SUM(Tabla10[[#This Row],[ALOJAMENTO]], Tabla10[[#This Row],[IMPOSTO]], Tabla10[[#This Row],[CARRO]]) -> 2341.2001
B28: LM | C28: =IF(D28="", "", INDEX(Colaboradores!A:A, MATCH(D28,Colaboradores!C:C, 0))) -> E1918 | D28: CRISTIAN CAMILO BORRE SILVA | E28: 46041 | G28: =IFERROR(VLOOKUP(Tabla10[[#This Row],[COD]],'TotalHorasAjustadas (2)'!D:L,8,FALSE),"") -> 103 | H28: 15 | I28: =IFERROR(VLOOKUP(Tabla10[[#This Row],[COD]],Alojamentos!B:P,11,FALSE),"") | J28: =IF(ISBLANK(Tabla10[[#This Row],[INICIO VINCULO]]), 0, MAX(0, MIN(IF(ISBLANK(Tabla10[[#This Row],[FIM VINCULO]]), DATE(2026,1,31), Tabla10[[#This Row],[FIM VINCULO]]), DATE(2026,1,31)) - MAX(Tabla10[[#This Row],[INICIO VINCULO]], DATE(2026,1,1)) + 1)) -> 13 | K28: =7.05806*Tabla10[[#This Row],[DIAS DE ALTA]] -> 91.75478 | L28: =IFERROR(VLOOKUP(Tabla10[[#This Row],[COD]],Carro!B:D,3,FALSE),"") | M28: =IFERROR(VLOOKUP(Tabla10[[#This Row],[COD]],'Outros descontos'!B:P,15,FALSE),"") | N28: =(Tabla10[[#This Row],[HORAS TRABALHADAS]]*Tabla10[[#This Row],[TARIFA]]) - SUM(Tabla10[[#This Row],[ALOJAMENTO]], Tabla10[[#This Row],[IMPOSTO]], Tabla10[[#This Row],[CARRO]]) -> 1453.2452
B29: KI | C29: =IF(D29="", "", INDEX(Colaboradores!A:A, MATCH(D29,Colaboradores!C:C, 0))) -> E1895 | D29: DAMIAN ZAMBRANO TULANDE | E29: 45762 | F29: 46052 | G29: =IFERROR(VLOOKUP(Tabla10[[#This Row],[COD]],'TotalHorasAjustadas (2)'!D:L,8,FALSE),"") -> 142 | H29: =IFERROR(VLOOKUP(Tabla10[[#This Row],[COD]],Tabla15[],4,FALSE),"") -> 15 | I29: =IFERROR(VLOOKUP(Tabla10[[#This Row],[COD]],Alojamentos!B:P,11,FALSE),"") | J29: =IF(ISBLANK(Tabla10[[#This Row],[INICIO VINCULO]]), 0, MAX(0, MIN(IF(ISBLANK(Tabla10[[#This Row],[FIM VINCULO]]), DATE(2026,1,31), Tabla10[[#This Row],[FIM VINCULO]]), DATE(2026,1,31)) - MAX(Tabla10[[#This Row],[INICIO VINCULO]], DATE(2026,1,1)) + 1)) -> 30 | K29: =7.05806*Tabla10[[#This Row],[DIAS DE ALTA]] -> 211.7418 | L29: =IFERROR(VLOOKUP(Tabla10[[#This Row],[COD]],Carro!B:D,3,FALSE),"") -> 66.666667 | M29: =IFERROR(VLOOKUP(Tabla10[[#This Row],[COD]],'Outros descontos'!B:P,15,FALSE),"") | N29: =(Tabla10[[#This Row],[HORAS TRABALHADAS]]*Tabla10[[#This Row],[TARIFA]]) - SUM(Tabla10[[#This Row],[ALOJAMENTO]], Tabla10[[#This Row],[IMPOSTO]], Tabla10[[#This Row],[CARRO]]) -> 1851.5915
B30: KI | C30: =IF(D30="", "", INDEX(Colaboradores!A:A, MATCH(D30,Colaboradores!C:C, 0))) -> E0534 | D30: DANILO RAMIREZ SARATE | E30: 45762 | F30: 46027 | G30: 0 | H30: =IFERROR(VLOOKUP(Tabla10[[#This Row],[COD]],Tabla15[],4,FALSE),"") -> 15 | I30: =IFERROR(VLOOKUP(Tabla10[[#This Row],[COD]],Alojamentos!B:P,11,FALSE),"") | J30: =IF(ISBLANK(Tabla10[[#This Row],[INICIO VINCULO]]), 0, MAX(0, MIN(IF(ISBLANK(Tabla10[[#This Row],[FIM VINCULO]]), DATE(2026,1,31), Tabla10[[#This Row],[FIM VINCULO]]), DATE(2026,1,31)) - MAX(Tabla10[[#This Row],[INICIO VINCULO]], DATE(2026,1,1)) + 1)) -> 5 | K30: =7.05806*Tabla10[[#This Row],[DIAS DE ALTA]] -> 35.2903 | L30: =IFERROR(VLOOKUP(Tabla10[[#This Row],[COD]],Carro!B:D,3,FALSE),"") | M30: =IFERROR(VLOOKUP(Tabla10[[#This Row],[COD]],'Outros descontos'!B:P,15,FALSE),"") | N30: 0
B31: WS | C31: =IF(D31="", "", INDEX(Colaboradores!A:A, MATCH(D31,Colaboradores!C:C, 0))) -> E1663 | D31: DARIO CARLOS MANUEL PEREIRA | E31: 45945 | G31: =IFERROR(VLOOKUP(Tabla10[[#This Row],[COD]],'TotalHorasAjustadas (2)'!D:L,8,FALSE),"") -> 102 | H31: =IFERROR(VLOOKUP(Tabla10[[#This Row],[COD]],Tabla15[],4,FALSE),"") -> 15 | I31: =IFERROR(VLOOKUP(Tabla10[[#This Row],[COD]],Alojamentos!B:P,11,FALSE),"") | J31: =IF(ISBLANK(Tabla10[[#This Row],[INICIO VINCULO]]), 0, MAX(0, MIN(IF(ISBLANK(Tabla10[[#This Row],[FIM VINCULO]]), DATE(2026,1,31), Tabla10[[#This Row],[FIM VINCULO]]), DATE(2026,1,31)) - MAX(Tabla10[[#This Row],[INICIO VINCULO]], DATE(2026,1,1)) + 1)) -> 31 | K31: =7.05806*Tabla10[[#This Row],[DIAS DE ALTA]] -> 218.79986 | L31: =IFERROR(VLOOKUP(Tabla10[[#This Row],[COD]],Carro!B:D,3,FALSE),"") | M31: =IFERROR(VLOOKUP(Tabla10[[#This Row],[COD]],'Outros descontos'!B:P,15,FALSE),"") | N31: =(Tabla10[[#This Row],[HORAS TRABALHADAS]]*Tabla10[[#This Row],[TARIFA]]) - SUM(Tabla10[[#This Row],[ALOJAMENTO]], Tabla10[[#This Row],[IMPOSTO]], Tabla10[[#This Row],[CARRO]]) -> 1311.2001
B32: WS | C32: =IF(D32="", "", INDEX(Colaboradores!A:A, MATCH(D32,Colaboradores!C:C, 0))) -> E0578 | D32: DIEGO ROBERTO SOUZA SCAVACINI | E32: 45873 | G32: =IFERROR(VLOOKUP(Tabla10[[#This Row],[COD]],'TotalHorasAjustadas (2)'!D:L,8,FALSE),"") -> 76 | H32: =IFERROR(VLOOKUP(Tabla10[[#This Row],[COD]],Tabla15[],4,FALSE),"") -> 17 | I32: =IFERROR(VLOOKUP(Tabla10[[#This Row],[COD]],Alojamentos!B:P,11,FALSE),"") | J32: =IF(ISBLANK(Tabla10[[#This Row],[INICIO VINCULO]]), 0, MAX(0, MIN(IF(ISBLANK(Tabla10[[#This Row],[FIM VINCULO]]), DATE(2026,1,31), Tabla10[[#This Row],[FIM VINCULO]]), DATE(2026,1,31)) - MAX(Tabla10[[#This Row],[INICIO VINCULO]], DATE(2026,1,1)) + 1)) -> 31 | K32: =7.05806*Tabla10[[#This Row],[DIAS DE ALTA]] -> 218.79986 | L32: =IFERROR(VLOOKUP(Tabla10[[#This Row],[COD]],Carro!B:D,3,FALSE),"") | M32: =IFERROR(VLOOKUP(Tabla10[[#This Row],[COD]],'Outros descontos'!B:P,15,FALSE),"") | N32: =(Tabla10[[#This Row],[HORAS TRABALHADAS]]*Tabla10[[#This Row],[TARIFA]]) - SUM(Tabla10[[#This Row],[ALOJAMENTO]], Tabla10[[#This Row],[IMPOSTO]], Tabla10[[#This Row],[CARRO]]) -> 1073.2001
B33: WS | C33: =IF(D33="", "", INDEX(Colaboradores!A:A, MATCH(D33,Colaboradores!C:C, 0))) -> E1826 | D33: DOMINGO RAMON VEGA HUMANEZ | E33: 46052 | G33: =IFERROR(VLOOKUP(Tabla10[[#This Row],[COD]],'TotalHorasAjustadas (2)'!D:L,8,FALSE),"") -> 172.5 | H33: =IFERROR(VLOOKUP(Tabla10[[#This Row],[COD]],Tabla15[],4,FALSE),"") -> 15 | I33: =IFERROR(VLOOKUP(Tabla10[[#This Row],[COD]],Alojamentos!B:P,11,FALSE),"") | J33: =IF(ISBLANK(Tabla10[[#This Row],[INICIO VINCULO]]), 0, MAX(0, MIN(IF(ISBLANK(Tabla10[[#This Row],[FIM VINCULO]]), DATE(2026,1,31), Tabla10[[#This Row],[FIM VINCULO]]), DATE(2026,1,31)) - MAX(Tabla10[[#This Row],[INICIO VINCULO]], DATE(2026,1,1)) + 1)) -> 2 | K33: =7.05806*Tabla10[[#This Row],[DIAS DE ALTA]] -> 14.11612 | L33: =IFERROR(VLOOKUP(Tabla10[[#This Row],[COD]],Carro!B:D,3,FALSE),"") | M33: =IFERROR(VLOOKUP(Tabla10[[#This Row],[COD]],'Outros descontos'!B:P,15,FALSE),"") | N33: 580.88 | O33: 2000
B34: WS | C34: =IF(D34="", "", INDEX(Colaboradores!A:A, MATCH(D34,Colaboradores!C:C, 0))) -> E1970 | D34: EDDIE DE JESUS ZARATE IGUARAN | E34: 46041 | G34: 48 | H34: =IFERROR(VLOOKUP(Tabla10[[#This Row],[COD]],Tabla15[],4,FALSE),"") -> 15 | I34: =IFERROR(VLOOKUP(Tabla10[[#This Row],[COD]],Alojamentos!B:P,11,FALSE),"") | J34: =IF(ISBLANK(Tabla10[[#This Row],[INICIO VINCULO]]), 0, MAX(0, MIN(IF(ISBLANK(Tabla10[[#This Row],[FIM VINCULO]]), DATE(2026,1,31), Tabla10[[#This Row],[FIM VINCULO]]), DATE(2026,1,31)) - MAX(Tabla10[[#This Row],[INICIO VINCULO]], DATE(2026,1,1)) + 1)) -> 13 | K34: =7.05806*Tabla10[[#This Row],[DIAS DE ALTA]] -> 91.75478 | L34: =IFERROR(VLOOKUP(Tabla10[[#This Row],[COD]],Carro!B:D,3,FALSE),"") -> 40 | M34: =IFERROR(VLOOKUP(Tabla10[[#This Row],[COD]],'Outros descontos'!B:P,15,FALSE),"") -> 112.93 | N34: =(Tabla10[[#This Row],[HORAS TRABALHADAS]]*Tabla10[[#This Row],[TARIFA]]) - SUM(Tabla10[[#This Row],[ALOJAMENTO]], Tabla10[[#This Row],[IMPOSTO]], Tabla10[[#This Row],[CARRO]]) -> 588.24522
B35: LM | C35: =IF(D35="", "", INDEX(Colaboradores!A:A, MATCH(D35,Colaboradores!C:C, 0))) -> E1970 | D35: EDDIE DE JESUS ZARATE IGUARAN | E35: 45951 | F35: 46034 | G35: 48 | H35: =IFERROR(VLOOKUP(Tabla10[[#This Row],[COD]],Tabla15[],4,FALSE),"") -> 15 | I35: =IFERROR(VLOOKUP(Tabla10[[#This Row],[COD]],Alojamentos!B:P,11,FALSE),"") | J35: =IF(ISBLANK(Tabla10[[#This Row],[INICIO VINCULO]]), 0, MAX(0, MIN(IF(ISBLANK(Tabla10[[#This Row],[FIM VINCULO]]), DATE(2026,1,31), Tabla10[[#This Row],[FIM VINCULO]]), DATE(2026,1,31)) - MAX(Tabla10[[#This Row],[INICIO VINCULO]], DATE(2026,1,1)) + 1)) -> 12 | K35: =7.05806*Tabla10[[#This Row],[DIAS DE ALTA]] -> 84.69672 | M35: =IFERROR(VLOOKUP(Tabla10[[#This Row],[COD]],'Outros descontos'!B:P,15,FALSE),"") -> 112.93 | N35: =(Tabla10[[#This Row],[HORAS TRABALHADAS]]*Tabla10[[#This Row],[TARIFA]]) - SUM(Tabla10[[#This Row],[ALOJAMENTO]], Tabla10[[#This Row],[IMPOSTO]], Tabla10[[#This Row],[CARRO]]) -> 635.30328
B36: LM | C36: =IF(D36="", "", INDEX(Colaboradores!A:A, MATCH(D36,Colaboradores!C:C, 0))) -> E2090 | D36: EDGAR CORRALES HOYOS | E36: 46041 | G36: =IFERROR(VLOOKUP(Tabla10[[#This Row],[COD]],'TotalHorasAjustadas (2)'!D:L,8,FALSE),"") -> 74 | H36: 15 | I36: =IFERROR(VLOOKUP(Tabla10[[#This Row],[COD]],Alojamentos!B:P,11,FALSE),"") | J36: =IF(ISBLANK(Tabla10[[#This Row],[INICIO VINCULO]]), 0, MAX(0, MIN(IF(ISBLANK(Tabla10[[#This Row],[FIM VINCULO]]), DATE(2026,1,31), Tabla10[[#This Row],[FIM VINCULO]]), DATE(2026,1,31)) - MAX(Tabla10[[#This Row],[INICIO VINCULO]], DATE(2026,1,1)) + 1)) -> 13 | K36: =7.05806*Tabla10[[#This Row],[DIAS DE ALTA]] -> 91.75478 | L36: =IFERROR(VLOOKUP(Tabla10[[#This Row],[COD]],Carro!B:D,3,FALSE),"") | M36: =IFERROR(VLOOKUP(Tabla10[[#This Row],[COD]],'Outros descontos'!B:P,15,FALSE),"") | N36: =(Tabla10[[#This Row],[HORAS TRABALHADAS]]*Tabla10[[#This Row],[TARIFA]]) - SUM(Tabla10[[#This Row],[ALOJAMENTO]], Tabla10[[#This Row],[IMPOSTO]], Tabla10[[#This Row],[CARRO]]) -> 1018.2452
B37: KI | C37: =IF(D37="", "", INDEX(Colaboradores!A:A, MATCH(D37,Colaboradores!C:C, 0))) -> E0600 | D37: EDGAR STEVEN PENAGOS CESPEDES | E37: 45364 | F37: 46052 | G37: =IFERROR(VLOOKUP(Tabla10[[#This Row],[COD]],'TotalHorasAjustadas (2)'!D:L,8,FALSE),"") -> 225 | H37: =IFERROR(VLOOKUP(Tabla10[[#This Row],[COD]],Tabla15[],4,FALSE),"") -> 16 | I37: =IFERROR(VLOOKUP(Tabla10[[#This Row],[COD]],Alojamentos!B:P,11,FALSE),"") | J37: =IF(ISBLANK(Tabla10[[#This Row],[INICIO VINCULO]]), 0, MAX(0, MIN(IF(ISBLANK(Tabla10[[#This Row],[FIM VINCULO]]), DATE(2026,1,31), Tabla10[[#This Row],[FIM VINCULO]]), DATE(2026,1,31)) - MAX(Tabla10[[#This Row],[INICIO VINCULO]], DATE(2026,1,1)) + 1)) -> 30 | K37: =7.05806*Tabla10[[#This Row],[DIAS DE ALTA]] -> 211.7418 | L37: =IFERROR(VLOOKUP(Tabla10[[#This Row],[COD]],Carro!B:D,3,FALSE),"") | M37: =IFERROR(VLOOKUP(Tabla10[[#This Row],[COD]],'Outros descontos'!B:P,15,FALSE),"") | N37: =(Tabla10[[#This Row],[HORAS TRABALHADAS]]*Tabla10[[#This Row],[TARIFA]]) - SUM(Tabla10[[#This Row],[ALOJAMENTO]], Tabla10[[#This Row],[IMPOSTO]], Tabla10[[#This Row],[CARRO]]) -> 3388.2582
B38: KI | C38: =IF(D38="", "", INDEX(Colaboradores!A:A, MATCH(D38,Colaboradores!C:C, 0))) -> E0161 | D38: EDILBERTO DOMINGUEZ PEREIRA | E38: 45762 | F38: 46053 | G38: =IFERROR(VLOOKUP(Tabla10[[#This Row],[COD]],'TotalHorasAjustadas (2)'!D:L,8,FALSE),"") -> 199 | H38: =IFERROR(VLOOKUP(Tabla10[[#This Row],[COD]],Tabla15[],4,FALSE),"") -> 18 | I38: =IFERROR(VLOOKUP(Tabla10[[#This Row],[COD]],Alojamentos!B:P,11,FALSE),"") | J38: =IF(ISBLANK(Tabla10[[#This Row],[INICIO VINCULO]]), 0, MAX(0, MIN(IF(ISBLANK(Tabla10[[#This Row],[FIM VINCULO]]), DATE(2026,1,31), Tabla10[[#This Row],[FIM VINCULO]]), DATE(2026,1,31)) - MAX(Tabla10[[#This Row],[INICIO VINCULO]], DATE(2026,1,1)) + 1)) -> 31 | K38: =7.05806*Tabla10[[#This Row],[DIAS DE ALTA]] -> 218.79986 | L38: =IFERROR(VLOOKUP(Tabla10[[#This Row],[COD]],Carro!B:D,3,FALSE),"") | M38: =IFERROR(VLOOKUP(Tabla10[[#This Row],[COD]],'Outros descontos'!B:P,15,FALSE),"") | N38: =(Tabla10[[#This Row],[HORAS TRABALHADAS]]*Tabla10[[#This Row],[TARIFA]]) - SUM(Tabla10[[#This Row],[ALOJAMENTO]], Tabla10[[#This Row],[IMPOSTO]], Tabla10[[#This Row],[CARRO]]) -> 3363.2001
B39: KR | C39: =IF(D39="", "", INDEX(Colaboradores!A:A, MATCH(D39,Colaboradores!C:C, 0))) -> E0615 | D39: EDILSON FIERRO DAGUA | E39: 45803 | F39: 46052 | G39: =IFERROR(VLOOKUP(Tabla10[[#This Row],[COD]],'TotalHorasAjustadas (2)'!D:L,8,FALSE),"") -> 227 | H39: =IFERROR(VLOOKUP(Tabla10[[#This Row],[COD]],Tabla15[],4,FALSE),"") -> 15 | I39: =IFERROR(VLOOKUP(Tabla10[[#This Row],[COD]],Alojamentos!B:P,11,FALSE),"") | J39: =IF(ISBLANK(Tabla10[[#This Row],[INICIO VINCULO]]), 0, MAX(0, MIN(IF(ISBLANK(Tabla10[[#This Row],[FIM VINCULO]]), DATE(2026,1,31), Tabla10[[#This Row],[FIM VINCULO]]), DATE(2026,1,31)) - MAX(Tabla10[[#This Row],[INICIO VINCULO]], DATE(2026,1,1)) + 1)) -> 30 | K39: =7.05806*Tabla10[[#This Row],[DIAS DE ALTA]] -> 211.7418 | L39: =IFERROR(VLOOKUP(Tabla10[[#This Row],[COD]],Carro!B:D,3,FALSE),"") -> 74.666667 | M39: =IFERROR(VLOOKUP(Tabla10[[#This Row],[COD]],'Outros descontos'!B:P,15,FALSE),"") | N39: =(Tabla10[[#This Row],[HORAS TRABALHADAS]]*Tabla10[[#This Row],[TARIFA]]) - SUM(Tabla10[[#This Row],[ALOJAMENTO]], Tabla10[[#This Row],[IMPOSTO]], Tabla10[[#This Row],[CARRO]]) -> 3118.5915
B40: LM | C40: =IF(D40="", "", INDEX(Colaboradores!A:A, MATCH(D40,Colaboradores!C:C, 0))) -> E0637 | D40: EDUAR MANUEL DAVILA CERON | E40: 46041 | G40: =IFERROR(VLOOKUP(Tabla10[[#This Row],[COD]],'TotalHorasAjustadas (2)'!D:L,8,FALSE),"") -> 102.5 | H40: 15 | I40: =IFERROR(VLOOKUP(Tabla10[[#This Row],[COD]],Alojamentos!B:P,11,FALSE),"") | J40: =IF(ISBLANK(Tabla10[[#This Row],[INICIO VINCULO]]), 0, MAX(0, MIN(IF(ISBLANK(Tabla10[[#This Row],[FIM VINCULO]]), DATE(2026,1,31), Tabla10[[#This Row],[FIM VINCULO]]), DATE(2026,1,31)) - MAX(Tabla10[[#This Row],[INICIO VINCULO]], DATE(2026,1,1)) + 1)) -> 13 | K40: =7.05806*Tabla10[[#This Row],[DIAS DE ALTA]] -> 91.75478 | L40: =IFERROR(VLOOKUP(Tabla10[[#This Row],[COD]],Carro!B:D,3,FALSE),"") | M40: =IFERROR(VLOOKUP(Tabla10[[#This Row],[COD]],'Outros descontos'!B:P,15,FALSE),"") | N40: =(Tabla10[[#This Row],[HORAS TRABALHADAS]]*Tabla10[[#This Row],[TARIFA]]) - SUM(Tabla10[[#This Row],[ALOJAMENTO]], Tabla10[[#This Row],[IMPOSTO]], Tabla10[[#This Row],[CARRO]]) -> 1445.7452
...

Sheet TotalHorasAjustadas (2)
A1: Cliente | B1: Empresa | C1: Funcion | D1: COD_colab | E1: Trabalhador | F1: Periodo_fat | G1: Total_Horas | H1: Dias_lancados | I1: Soma_qtd_hrs_old | J1: Soma_Qtd_hrs | K1: Total_Horas_Ajustado | L1: Dif_Horas
A2: 105-INGENIERIA PARA EL DESAROLLO TECNOLOGICO | B2: KOTRIK | C2: SOLDADOR TIG (GTAW) | D2: E1512 | E2: JOIN VILLEGAS | F2: 46023 | G2: 216 | H2: 31 | I2: 0 | J2: 0 | K2: 216 | L2: 0
A3: 105-INGENIERIA PARA EL DESAROLLO TECNOLOGICO | B3: KOTRIK | C3: SOLDADOR ELECTRODO (SMAW) | D3: E0354 | E3: SANTIAGO CELU YUBYINER | F3: 46023 | G3: 252 | H3: 31 | I3: 0 | J3: 0 | K3: 252 | L3: 0
A4: 148-MONTAJES GOMUR S.L | B4: KOTRIK | C4: CALDERERO / SOLDADOR (MIG-MAG) | D4: E1800 | E4: PABLO MANOLO ROMERO HUERTAS | F4: 46023 | G4: 208 | H4: 31 | I4: 0 | J4: 0 | K4: 208 | L4: 0
A5: 148-MONTAJES GOMUR S.L | B5: KOTRIK | C5: SOLDADOR ELECTRODO (SMAW) | D5: E0475 | E5: VICTOR GALVEZ PALACIOS | F5: 46023 | G5: 203 | H5: 31 | I5: 0 | J5: 0 | K5: 203 | L5: 0
A6: 148-MONTAJES GOMUR S.L | B6: KOTRIK | C6: SOLDADOR ELECTRODO (SMAW) | D6: E0474 | E6: ZEVALLOS BENITES JOSUE | F6: 46023 | G6: 173 | H6: 31 | I6: 0 | J6: 0 | K6: 173 | L6: 0
A7: 191-TALLERES LANDALICE SA | B7: KOTRIK | C7: SOLDADOR ELECTRODO (SMAW) | D7: E1359 | E7: LUIZ GUILHERME AMARAL ALVES | F7: 46023 | G7: 48 | H7: 31 | I7: 8 | J7: 2 | K7: 42 | L7: -6
A8: 203-TECNOLOGIA MECANICA I ELECTRA SLU | B8: KOTRIK | C8: SOLDADOR ELECTRODO (SMAW) | D8: E0592 | E8: DARWIN JOSE VASQUEZ ORTEGA | F8: 46023 | G8: 191.25 | H8: 31 | I8: 0 | J8: 0 | K8: 191.25 | L8: 0
A9: 203-TECNOLOGIA MECANICA I ELECTRA SLU | B9: KOTRIK | C9: SOLDADOR ELECTRODO (SMAW) | D9: E0591 | E9: JONATHAN BLANDON HINCAPIE | F9: 46023 | G9: 179 | H9: 31 | I9: 0 | J9: 0 | K9: 179 | L9: 0
A10: 225-CARVISA CONTAINER SLU | B10: KOTRIK | C10: SOLDADOR ELECTRODO (SMAW) | D10: E0001590 | E10: BAIRON BURBANO | F10: 46023 | G10: 142 | H10: 31 | I10: 0 | J10: 0 | K10: 142 | L10: 0
A11: 225-CARVISA CONTAINER SLU | B11: KOTRIK | C11: SOLDADOR ELECTRODO (SMAW) | D11: E0873 | E11: ELKIN GARZON LOPEZ | F11: 46023 | G11: 132 | H11: 31 | I11: 0 | J11: 0 | K11: 132 | L11: 0
A12: 225-CARVISA CONTAINER SLU | B12: KOTRIK | C12: SOLDADOR ELECTRODO (SMAW) | D12: E0890 | E12: FABIAN CERÓN | F12: 46023 | G12: 136 | H12: 31 | I12: 0 | J12: 0 | K12: 136 | L12: 0
A13: 30-CALDENOR | B13: KOTRIK | C13: SOLDADOR ELECTRODO (SMAW) | D13: E1895 | E13: DAMIAN ZAMBRANO | F13: 46023 | G13: 142 | H13: 31 | I13: 0 | J13: 0 | K13: 142 | L13: 0
A14: 30-CALDENOR | B14: KOTRIK | C14: SOLDADOR ELECTRODO (SMAW) | D14: E0125 | E14: EVALIO ANGULO | F14: 46023 | G14: 142 | H14: 31 | I14: 0 | J14: 0 | K14: 142 | L14: 0
A15: 30-CALDENOR | B15: KOTRIK | D15: E1415 | E15: JHON EINER INSUASTI TULANDE | F15: 46023 | G15: 142 | H15: 31 | I15: 0 | J15: 0 | K15: 142 | L15: 0
A16: 30-CALDENOR | B16: KOTRIK | C16: SOLDADOR MIG-MAG / ELECTRODO (GMAW / SMAW) | D16: E1818 | E16: WILBER LOPEZ BALETA | F16: 46023 | G16: 133 | H16: 31 | I16: 0 | J16: 0 | K16: 133 | L16: 0
A17: 42-CALDESOL | B17: KOTRIK | C17: SOLDADOR ELECTRODO (SMAW) | D17: E0146 | E17: JESUS CARDENAS RIVERA | F17: 46023 | G17: 354 | H17: 62 | I17: 0 | J17: 0 | K17: 354 | L17: 0
A18: 43-CAM IMPIANTI INDUSTRIALI SRL | B18: KOTRIK | C18: TUBERO | D18: E0166 | E18: ALVARO ROJAS | F18: 46023 | G18: 144 | H18: 31 | I18: 0 | J18: 0 | K18: 144 | L18: 0
A19: 43-CAM IMPIANTI INDUSTRIALI SRL | B19: KOTRIK | C19: TUBERO | D19: E0155 | E19: CARLOS A. RAMOS Q. | F19: 46023 | G19: 225 | H19: 31 | I19: 0 | J19: 0 | K19: 225 | L19: 0
A20: 43-CAM IMPIANTI INDUSTRIALI SRL | B20: KOTRIK | C20: AYUDANTE | D20: E0152 | E20: CARLOS ADRIAN CAMELO CALDERON | F20: 46023 | G20: 161 | H20: 31 | I20: 0 | J20: 0 | K20: 161 | L20: 0
A21: 43-CAM IMPIANTI INDUSTRIALI SRL | B21: KOTRIK | C21: SOLDADOR ELECTRODO (SMAW) | D21: E0161 | E21: EDILBERTO DOMINGUEZ | F21: 46023 | G21: 215 | H21: 31 | I21: 16 | J21: 0 | K21: 199 | L21: -16
A22: 43-CAM IMPIANTI INDUSTRIALI SRL | B22: KOTRIK | C22: SOLDADOR ELECTRODO (SMAW) | D22: E0151 | E22: GUILLERMO POSADA | F22: 46023 | G22: 215 | H22: 31 | I22: 0 | J22: 10 | K22: 225 | L22: 10
A23: 43-CAM IMPIANTI INDUSTRIALI SRL | B23: KOTRIK | C23: AYUDANTE | D23: E2070 | E23: HENÁN QUINTERO JARAMILLO | F23: 46023 | G23: 146 | H23: 31 | I23: 0 | J23: 0 | K23: 146 | L23: 0
A24: 43-CAM IMPIANTI INDUSTRIALI SRL | B24: KOTRIK | C24: SOLDADOR ELECTRODO (SMAW) | D24: E0123 | E24: JIM PAUL CHUNGA LUJAN | F24: 46023 | G24: 199 | H24: 31 | I24: 0 | J24: 0 | K24: 199 | L24: 0
A25: 43-CAM IMPIANTI INDUSTRIALI SRL | B25: KOTRIK | C25: TUBERO | D25: E0034 | E25: JORDY ALEXADER ALVA PAYAC | F25: 46023 | G25: 199 | H25: 31 | I25: 10 | J25: 7 | K25: 196 | L25: -3
A26: 43-CAM IMPIANTI INDUSTRIALI SRL | B26: KOTRIK | C26: SOLDADOR ELECTRODO (SMAW) | D26: E0164 | E26: JORGE ARLEY ALVAREZ GONZALEZ | F26: 46023 | G26: 199 | H26: 31 | I26: 0 | J26: 0 | K26: 199 | L26: 0
A27: 43-CAM IMPIANTI INDUSTRIALI SRL | B27: KOTRIK | C27: TUBERO | D27: E0163 | E27: JOSE DE JESUS MENDOZA | F27: 46023 | G27: 162 | H27: 31 | I27: 0 | J27: 0 | K27: 162 | L27: 0
A28: 43-CAM IMPIANTI INDUSTRIALI SRL | B28: KOTRIK | C28: AYUDANTE | D28: E1751 | E28: NELSON JAIME PITRE CASTILLA | F28: 46023 | G28: 147 | H28: 31 | I28: 0 | J28: 0 | K28: 147 | L28: 0
A29: 43-CAM IMPIANTI INDUSTRIALI SRL | B29: KOTRIK | D29: E1426 | E29: RENZO CHUNGA LUJAN | F29: 46023 | G29: 199 | H29: 31 | I29: 0 | J29: 0 | K29: 199 | L29: 0
A30: 43-CAM IMPIANTI INDUSTRIALI SRL | B30: KOTRIK | C30: TUBERO | D30: E0116 | E30: ROGER HALDER CHILCA LEON | F30: 46023 | G30: 180 | H30: 31 | I30: 0 | J30: 0 | K30: 180 | L30: 0
A31: 43-CAM IMPIANTI INDUSTRIALI SRL | B31: KOTRIK | C31: TUBERO | D31: E0036 | E31: ROLANDO CATUNTA M. | F31: 46023 | G31: 199 | H31: 31 | I31: 0 | J31: 0 | K31: 199 | L31: 0
A32: 43-CAM IMPIANTI INDUSTRIALI SRL | B32: KOTRIK | C32: SOLDADOR TIG / ELECTRODO (GTAW / SMAW) | D32: E0600 | E32: STIVEN PENAGOS | F32: 46023 | G32: 225 | H32: 31 | I32: 0 | J32: 0 | K32: 225 | L32: 0
A33: 43-CAM IMPIANTI INDUSTRIALI SRL | B33: KOTRIK | C33: SOLDADOR ELECTRODO (SMAW) | D33: E0296 | E33: WILMER YANAYACO | F33: 46023 | G33: 188 | H33: 31 | I33: 0 | J33: 0 | K33: 188 | L33: 0
A34: 43-CAM IMPIANTI INDUSTRIALI SRL | B34: KOTRIK | C34: TUBERO | D34: E1788 | E34: YANNY ALBERTO HERNANDEZ LOZANO | F34: 46023 | G34: 235 | H34: 31 | I34: 10 | J34: 0 | K34: 225 | L34: -10
A35: 43-CAM IMPIANTI INDUSTRIALI SRL | B35: KOTRIK | C35: TUBERO | D35: E0032 | E35: YOBER HUAMAN VELASQUEZ | F35: 46023 | G35: 144 | H35: 31 | I35: 0 | J35: 0 | K35: 144 | L35: 0
A36: 71-ELYTT ENERGY | B36: KOTRIK | C36: SOLDADOR ELECTRODO (SMAW) | D36: E0615 | E36: EDILSON FIERRO | F36: 46023 | G36: 227 | H36: 31 | I36: 0 | J36: 0 | K36: 227 | L36: 0
A37: 71-ELYTT ENERGY | B37: KOTRIK | C37: SOLDADOR ELECTRODO (SMAW) | D37: E0237 | E37: FREDY JAVIER CCALLA ROJAS | F37: 46023 | G37: 248 | H37: 31 | I37: 0 | J37: 0 | K37: 248 | L37: 0
A38: 71-ELYTT ENERGY | B38: KOTRIK | C38: SOLDADOR ELECTRODO (SMAW) | D38: E0240 | E38: HECTOR LUIS PARRAGA ZAVALA | F38: 46023 | G38: 252 | H38: 31 | I38: 0 | J38: 0 | K38: 252 | L38: 0
A39: 71-ELYTT ENERGY | B39: KOTRIK | C39: SOLDADOR ELECTRODO (SMAW) | D39: E0238 | E39: ISRAEL BENAVIDES PRECIADO | F39: 46023 | G39: 276 | H39: 31 | I39: 0 | J39: 0 | K39: 276 | L39: 0
A40: 71-ELYTT ENERGY | B40: KOTRIK | D40: E1416 | E40: JHON JAIRO MUÑOZ BARBOSA | F40: 46023 | G40: 307 | H40: 31 | I40: 0 | J40: 0 | K40: 307 | L40: 0
...

Sheet Tarifas dezembro att
D2: Cod trabalhador | E2: Colaborador | F2: Nome cliente 1 | G2: Tarifa cliente 1
D3: E1704 | E3: ELICEO FUENTES PARRA | F3: AEB DRYTECH | G3: 16
D4: E1671 | E4: JORGE ENRIQUE SANABRIA MORENO | F4: AEB DRYTECH | G4: 16
D5: E1754 | E5: NORVEY GONZALEZ LOPEZ | F5: AEB DRYTECH | G5: 16
D6: E0620 | E6: REMY SENNDER FARIAS ACARO | F6: AEB DRYTECH | G6: 16
D7: E0058 | E7: HENRRY CASTRO COLLACHAGUA | F7: ALUMINIO YACHT COSTA SL | G7: 15
D8: E0062 | E8: AYRTON MAXIMO CUMPA SENADOR | F8: ARDANORE | G8: 15
D9: E0063 | E9: CESAR EDUARDO GONZALES BARRIENTOS | F9: ARDANORE | G9: 15
D10: E0064 | E10: JAIME MANOLO ALVAREZ TORRES | F10: ARDANORE | G10: 15
D11: E0067 | E11: JAVIER SAUL PEREA CAMARGO | F11: ARDANORE | G11: 15
D12: E0065 | E12: JESUS ALBERTO GONZALES FERNANDEZ | F12: ARDANORE | G12: 15
D13: E0066 | E13: LUIS ALBERTO RAMIREZ PINEDO | F13: ARDANORE | G13: 15
D14: E0061 | E14: SIMION LUCIANO CHILINGANO PILLACA | F14: ARDANORE | G14: 15
... D422: E0593 | E422: ALEX MAURICIO CARDONA RAMIREZ | F422: TOKIO METAL | G422: 15

Sheet Informações
B5: Previsão | E5: Total general | L5: Total general | P5: Previsão | S5: Total general | W5: Previsão | Z5: Total general
B6: Etiquetas de fila | C6: Suma de Valor previsão de folha | E6: Etiquetas de fila | F6: Suma de Liquido total | I6: Etiquetas de fila | J6: Suma de Valor previsão de folha | L6: Etiquetas de fila | M6: Suma de Liquido total | P6: Rótulos de Linha | Q6: Suma de Valor previsão de folha | S6: Rótulos de Linha | T6: Suma de Liquido total | W6: Etiquetas de fila | X6: Suma de Valor previsão de folha | Z6: Etiquetas de fila | AA6: Suma de Liquido total
B7: Ativo | C7: 26061.387 | E7: Ativo | F7: 25221.387 | I7: Ativo | J7: 59508.195 | L7: Ativo | M7: 59508.195 | P7: Ativo | Q7: 95502.527 | S7: Ativo | T7: 94330.027 | W7: Ativo | X7: 87270.985 | Z7: Ativo | AA7: 86369.485
B8: Não ativo | C8: 90076.542 | E8: Não ativo | F8: 89836.542 | I8: Não ativo | J8: 54285.071 | L8: Não ativo | M8: 54285.071 | P8: Não ativo | Q8: 282185.52 | S8: Não ativo | T8: 298030.77 | W8: Não ativo | X8: 146093.77 | Z8: Não ativo | AA8: 143426.77
B9: Total general | C9: 116137.93 | E9: Total general | F9: 115057.93 | I9: Total general | J9: 113793.27 | L9: Total general | M9: 113793.27 | P9: Total Geral | Q9: 377688.05 | S9: Total Geral | T9: 392360.8 | W9: Total general | X9: 233364.75 | Z9: Total general | AA9: 229796.25
P12: Cuenta de Colaborador
B13: Cuenta de Colaborador | E13: Banco | F13: 213335.37 | I13: Cuenta de Colaborador | L13: Banco | M13: 254049.84 | P13: 163 | S13: Banco | T13: 852000 | Z13: Banco | AA13: 375000
B14: 43 | E14: Diferença | F14: =F13-GETPIVOTDATA("Liquido total",$E$6) -> 98277.441 | I14: 50 | L14: Diferença | M14: =M13-GETPIVOTDATA("Liquido total",$L$6) -> 140256.57 | S14: Diferença | T14: =T13-GETPIVOTDATA("Liquido total",$S$6) -> 459639.2 | Z14: Diferença | AA14: =AA13-GETPIVOTDATA("Liquido total",$Z$6) -> 145203.75
B19: Altas Segurança Social | I19: Altas Segurança Social | P19: Altas Segurança Social | W19: Altas Segurança Social
B20: Etiquetas de fila | C20: Cuenta de Status SS | I20: Etiquetas de fila | J20: Cuenta de Status SS | P20: Rótulos de Linha | Q20: Cuenta de Status SS | W20: Etiquetas de fila | X20: Cuenta de Status SS
B21: Ativo | C21: 11 | I21: Ativo | J21: 26 | P21: Ativo | Q21: 42 | W21: Ativo | X21: 46
B22: Não ativo | C22: 32 | I22: Não ativo | J22: 24 | P22: Não ativo | Q22: 121 | W22: Não ativo | X22: 73
B23: Total general | C23: 43 | I23: Total general | J23: 50 | P23: Total Geral | Q23: 163 | W23: Total general | X23: 119
B26: Valores | E26: Valores | I26: Valores
B27: Suma de Auxilio alojamento | C27: 910 | E27: Suma de Imposto ss | F27: 2117.4 | I27: Suma de Auxilio alojamento | J27: 4800
B28: Suma de Outros acréscimos | E28: Suma de Adiantamento | F28: 200 | I28: Suma de Outros acréscimos
E29: Suma de Desconto Carro | F29: 1340.1111
E30: Suma de Outros descontos
E31: Suma de Taxa bancária | F31: 175.44
B34: Etiquetas de fila | C34: Suma de Liquido total | I34: Etiquetas de fila | J34: Suma de Liquido total
B35: Pendente | C35: 115057.93 | I35: Pendente | J35: 111564.09
B36: Total general | C36: 115057.93 | I36: Pago | J36: 2229.18
I37: Total general | J37: 113793.27

Sheet Confirmaçoes
B2: auxilio alojamento | G2: Impostos | L2: Adiantamentos | Q2: Desconto carro | V2: Suministros | AA2: Multas | AF2: Limpeza e danos | AK2: Tarifa
B4: ID | C4: Nomes | D4: valor | E4: Revisão | G4: ID | H4: Nomes | I4: valor | J4: Revisão | L4: ID | M4: Nomes | N4: valor | O4: Revisão | Q4: ID | R4: Nomes | S4: valor | T4: Revisão | V4: ID | W4: Nomes | X4: valor | Y4: Revisão | AA4: ID | AB4: Nomes | AC4: valor | AD4: Revisão | AF4: ID | AG4: Nomes | AH4: valor | AI4: Revisão | AK4: ID | AL4: Nomes | AM4: valor | AN4: Revisão
B5: KR | C5: ALAN FRANCISCO NAVAS DIAZ | G5: KR | H5: ALAN FRANCISCO NAVAS DIAZ | I5: 218.798 | L5: KR | M5: ALAN FRANCISCO NAVAS DIAZ | Q5: KR | R5: ALAN FRANCISCO NAVAS DIAZ | V5: KI | W5: ALVARO ENRIQUE ROJAS DE LA OSSA | AA5: KR | AB5: ALAN FRANCISCO NAVAS DIAZ | AF5: KR | AG5: ALAN FRANCISCO NAVAS DIAZ | AK5: KR | AL5: ALAN FRANCISCO NAVAS DIAZ | AM5: 13
B6: LM | C6: ALAN GERSON RAMIREZ ACARO | G6: LM | H6: ALAN GERSON RAMIREZ ACARO | I6: 0 | L6: LM | M6: ALAN GERSON RAMIREZ ACARO | Q6: LM | R6: ALAN GERSON RAMIREZ ACARO | S6: 106.66667 | V6: KI | W6: BAIRON RENE BURBANO MORALES | Y6: OK | AA6: LM | AB6: ALAN GERSON RAMIREZ ACARO | AF6: LM | AG6: ALAN GERSON RAMIREZ ACARO | AK6: LM | AL6: ALAN GERSON RAMIREZ ACARO | AM6: 15
B7: WS | C7: ALBEIRO OBANDO MICOLTA | D7: 300 | G7: WS | H7: ALBEIRO OBANDO MICOLTA | I7: 218.798 | L7: WS | M7: ALBEIRO OBANDO MICOLTA | Q7: WS | R7: ALBEIRO OBANDO MICOLTA | V7: KI | W7: CAMILO ANDRES VALERO PEREZ | AA7: WS | AB7: ALBEIRO OBANDO MICOLTA | AF7: WS | AG7: ALBEIRO OBANDO MICOLTA | AK7: WS | AL7: ALBEIRO OBANDO MICOLTA | AM7: 17
B8: WS | C8: ALEX DAVID GOMEZ VILLADA | G8: WS | H8: ALEX DAVID GOMEZ VILLADA | I8: 0 | L8: WS | M8: ALEX DAVID GOMEZ VILLADA | Q8: WS | R8: ALEX DAVID GOMEZ VILLADA | V8: KI | W8: CARLOS ADRIAN CAMELO CALDERON | AA8: WS | AB8: ALEX DAVID GOMEZ VILLADA | AF8: WS | AG8: ALEX DAVID GOMEZ VILLADA | AK8: WS | AL8: ALEX DAVID GOMEZ VILLADA | AM8: 15
B9: KR | C9: ALEX MAURICIO CARDONA RAMIREZ | G9: KR | H9: ALEX MAURICIO CARDONA RAMIREZ | I9: 0 | L9: KR | M9: ALEX MAURICIO CARDONA RAMIREZ | Q9: KR | R9: ALEX MAURICIO CARDONA RAMIREZ | V9: KI | W9: CARLOS ALBERTO RAMOS URBANO | AA9: KR | AB9: ALEX MAURICIO CARDONA RAMIREZ | AF9: KR | AG9: ALEX MAURICIO CARDONA RAMIREZ | AK9: KR | AL9: ALEX MAURICIO CARDONA RAMIREZ | AM9: 15
