Workbook

Sheet Informaciones
G7: {=_xlfn._xlws.FILTER(Tabla1[[TRABAJADOR]:[IBAN]], (MONTH(Tabla1[FECHA ÚLTIMO CAMBIO]) = MONTH(TODAY())) * (YEAR(Tabla1[FECHA ÚLTIMO CAMBIO]) = YEAR(TODAY())) + (MONTH(Tabla1[FECHA ÚLTIMO CAMBIO]) = MONTH(TODAY())-1) * (YEAR(Tabla1[FECHA ÚLTIMO CAMBIO]) = YEAR(TODAY())))} -> ALBERTO ISMAEL MENDIETA CACERES | H7: BE93 9052 9049 1967 | N7: {=_xlfn._xlws.FILTER(Tabla1[TRABAJADOR], Tabla1[IBAN]="Pendiente", "Sin resultados")} -> JHEFRIN ALEXANDER GONZALEZ PADILLA
G8: ALBERTO RICHELLI DA SILVA | H8: PT50 0018 0003 5744 3293 0201 5 | K8: =COUNTIF('Control General'!D:D, "pendiente") -> 5 | N8: JOEL MAGALHAES
C9: {=SUMPRODUCT((MONTH(Tabla1[FECHA ÚLTIMO CAMBIO]) = MONTH(TODAY())) * (YEAR(Tabla1[FECHA ÚLTIMO CAMBIO]) = YEAR(TODAY())) + (MONTH(Tabla1[FECHA ÚLTIMO CAMBIO]) = MONTH(TODAY())-1) * (YEAR(Tabla1[FECHA ÚLTIMO CAMBIO]) = YEAR(TODAY())))} -> 61 | G9: ALDEMAR DOMINGUEZ CERCADO | H9: ES55 0182 1214 3302 0162 4902 | N9: JOHN FREDY QUINONES HENAO
G10: ALEXANDER GUZMAN | H10: ES29 6893 0001 7400 0036 7834 | N10: JOSE ARBEY CORREA RUIZ
G11: ALVARO ENRIQUE ROJAS DE LA OSSA | H11: NL02 BUNQ 2185 0437 57 | N11: SANTIAGO CASTRO RODRIGUEZ
G12: ANDY LYONEL CARRASCO VARGAS | H12: ES27 2100 1553 6902 0037 4216
G13: ANGEL RAFAEL DIAZ GUTIERREZ | H13: ES90 0182 0581 1202 0160 1758
G14: ANTONY ALEXANDER HERNANDEZ CHIRINOS | H14: ES71 0182 5322 2100 0296 1488
G15: APOLINAR GARCIA HERNANDEZ | H15: ES08 6893 0001 7600 0034 6871
G16: BOLIVAR GABRIEL ALDANA RAMIREZ | H16: BE29 9675 5422 9064
G17: BYRON YESID SUAREZ CUADRADO | H17: ES74 0182 9035 1102 0173 4235
G18: CARLOS ALBERTO CARDONA YAIMA | H18: ES88 0182 5900 0902 0157 1022
G19: CARLOS JULIO CANON | H19: ES71 2100 0868 5902 0107 2129
G20: CARLOS MARIO JARAMILLO LOPEZ | H20: ES25 0182 0838 6502 0157 5647
G21: CESAR NORBEY PENAGOS DUQUE | H21: ES85 6893 0001 7300 0034 1558
G22: CLAUDEMIR DO NASCIMENTO FURTADO | H22: BE67 9676 0947 2887
G23: CRISTIAN RAFAEL ORDONEZ AGUIRRE | H23: ES32 0182 5319 7700 0083 4229
... G67: YORVY RAFAEL MARTINEZ ROMERO | H67: ES45 0182 5011 1002 0224 2623

Sheet Control General
A3: N | B3: ID | C3: TRABAJADOR | D3: IBAN | E3: BANCO | F3: CERT. DE TITUL. | G3: FECHA ÚLTIMO CAMBIO | H3: DOCUM. FIRMADO | I3: EMPRESA | J3: OBSERVACIONES | K3: NOTAS
A4: {=_xlfn.SEQUENCE(2000)} -> 1 | B4: =IF(Tabla1[[#This Row],[TRABAJADOR]]="", "", VLOOKUP(Tabla1[[#This Row],[TRABAJADOR]], 'Colaborador ID'!B:C, 2, FALSE)) -> E0530 | C4: ABDELFAHAM OUBOUZID | D4: FR76 1659 8000 0131 9171 7000 163 | E4: NICKEL | F4: #VALUE! | G4: 45790 | H4: #VALUE!
A5: 2 | B5: =IF(Tabla1[[#This Row],[TRABAJADOR]]="", "", VLOOKUP(Tabla1[[#This Row],[TRABAJADOR]], 'Colaborador ID'!B:C, 2, FALSE)) -> E1855 | C5: ABDRUBAL FONSECA RINCON | D5: ES16 0182 2247 0702 0167 7660 | E5: BBVA | F5: #VALUE! | G5: 45958 | H5: #VALUE!
A6: 3 | B6: =IF(Tabla1[[#This Row],[TRABAJADOR]]="", "", VLOOKUP(Tabla1[[#This Row],[TRABAJADOR]], 'Colaborador ID'!B:C, 2, FALSE)) -> E0663 | C6: ABEL ANTONIO CUESTA CIFUENTES | D6: BE13 9050 1484 4239 | E6: WISE | F6: #VALUE! | H6: #VALUE!
A7: 4 | B7: =IF(Tabla1[[#This Row],[TRABAJADOR]]="", "", VLOOKUP(Tabla1[[#This Row],[TRABAJADOR]], 'Colaborador ID'!B:C, 2, FALSE)) -> E0513 | C7: ABRAHAM DAVID HOYOS ALVAREZ | D7: ES68 0182 0702 3702 0165 0072 | E7: BBVA | F7: #VALUE! | H7: #VALUE! | I7: STOCCO
A8: 5 | B8: =IF(Tabla1[[#This Row],[TRABAJADOR]]="", "", VLOOKUP(Tabla1[[#This Row],[TRABAJADOR]], 'Colaborador ID'!B:C, 2, FALSE)) -> E0432 | C8: ADALBERTO ARAGON GOMEZ | D8: BE53 9050 1170 2853 | E8: WISE | F8: #VALUE! | H8: #VALUE!
A9: 6 | B9: =IF(Tabla1[[#This Row],[TRABAJADOR]]="", "", VLOOKUP(Tabla1[[#This Row],[TRABAJADOR]], 'Colaborador ID'!B:C, 2, FALSE)) -> E0687 | C9: ADILSON ESCOBAR OREJUELA | D9: ES71 6893 0001 7100 0030 4078 | E9: NICKEL | F9: #VALUE! | G9: 45891 | H9: #VALUE! | I9: STOCCO
A10: 7 | B10: =IF(Tabla1[[#This Row],[TRABAJADOR]]="", "", VLOOKUP(Tabla1[[#This Row],[TRABAJADOR]], 'Colaborador ID'!B:C, 2, FALSE)) -> E0570 | C10: ADRIAN CAMILO PINILLA AGUIRRE | D10: ES88 0182 4590 1202 0161 8527 | E10: BBVA | F10: #VALUE! | G10: 45783 | H10: #VALUE!
A11: 8 | B11: =IF(Tabla1[[#This Row],[TRABAJADOR]]="", "", VLOOKUP(Tabla1[[#This Row],[TRABAJADOR]], 'Colaborador ID'!B:C, 2, FALSE)) -> E0452 | C11: ADRIAN CARLOSAMA CHAVEZ | D11: BE31 9051 9847 6555 | E11: WISE | F11: #VALUE! | H11: #VALUE!
A12: 9 | B12: =IF(Tabla1[[#This Row],[TRABAJADOR]]="", "", VLOOKUP(Tabla1[[#This Row],[TRABAJADOR]], 'Colaborador ID'!B:C, 2, FALSE)) -> E0516 | C12: AGNER MARTINEZ CARREAZO | D12: ES11 0049 3121 9220 1430 8753 | E12: SANTANDER | F12: #VALUE! | H12: #VALUE!
A13: 10 | B13: =IF(Tabla1[[#This Row],[TRABAJADOR]]="", "", VLOOKUP(Tabla1[[#This Row],[TRABAJADOR]], 'Colaborador ID'!B:C, 2, FALSE)) -> E0814 | C13: AGUINALDO JOSE DA SILVA SOUZA | D13: PT50 0033 0000 4563 9326 4410 5 | E13: MILLENNIUM | F13: #VALUE! | G13: 45761 | H13: #VALUE!
A14: 11 | B14: =IF(Tabla1[[#This Row],[TRABAJADOR]]="", "", VLOOKUP(Tabla1[[#This Row],[TRABAJADOR]], 'Colaborador ID'!B:C, 2, FALSE)) -> E0194 | C14: ALAN FRANCISCO NAVAS DIAZ | D14: ES43 0182 0706 1902 0164 4996 | E14: BBVA | F14: #VALUE! | H14: #VALUE!
A15: 12 | B15: =IF(Tabla1[[#This Row],[TRABAJADOR]]="", "", VLOOKUP(Tabla1[[#This Row],[TRABAJADOR]], 'Colaborador ID'!B:C, 2, FALSE)) -> E0406 | C15: ALAN GERSON RAMIREZ ACARO | D15: ES21 1576 1212 1910 1041 2202 | E15: BUNQ | F15: #VALUE! | G15: 45726 | H15: #VALUE!
A16: 13 | B16: =IF(Tabla1[[#This Row],[TRABAJADOR]]="", "", VLOOKUP(Tabla1[[#This Row],[TRABAJADOR]], 'Colaborador ID'!B:C, 2, FALSE)) -> E1402 | C16: ALBEIRO CARDOZO HEREDIA | D16: ES46 0182 8151 8902 0193 8271 | E16: BBVA | F16: #VALUE! | G16: 45849 | H16: #VALUE!
A17: 14 | B17: =IF(Tabla1[[#This Row],[TRABAJADOR]]="", "", VLOOKUP(Tabla1[[#This Row],[TRABAJADOR]], 'Colaborador ID'!B:C, 2, FALSE)) -> E0347 | C17: ALBEIRO ENRIQUE AMOR AGUILAR | D17: LT85 3250 0126 1672 5392 | E17: REVOLUT | F17: #VALUE! | H17: #VALUE!
A18: 15 | B18: =IF(Tabla1[[#This Row],[TRABAJADOR]]="", "", VLOOKUP(Tabla1[[#This Row],[TRABAJADOR]], 'Colaborador ID'!B:C, 2, FALSE)) -> E0272 | C18: ALBEIRO OBANDO MICOLTA | D18: ES64 0182 1216 2502 0159 8939 | E18: BBVA | F18: #VALUE! | G18: 45938 | H18: #VALUE!
A19: 16 | B19: =IF(Tabla1[[#This Row],[TRABAJADOR]]="", "", VLOOKUP(Tabla1[[#This Row],[TRABAJADOR]], 'Colaborador ID'!B:C, 2, FALSE)) -> E0189 | C19: ALBERTO CCENHUA MICHCA | D19: ES92 0182 0635 5102 0163 1740 | E19: BBVA | F19: #VALUE! | G19: 45762 | H19: #VALUE!
A20: 17 | B20: =IF(Tabla1[[#This Row],[TRABAJADOR]]="", "", VLOOKUP(Tabla1[[#This Row],[TRABAJADOR]], 'Colaborador ID'!B:C, 2, FALSE)) -> E0208 | C20: ALBERTO DURAN | D20: BE86 9052 9845 3950 | E20: WISE | F20: #VALUE! | H20: #VALUE!
A21: 18 | B21: =IF(Tabla1[[#This Row],[TRABAJADOR]]="", "", VLOOKUP(Tabla1[[#This Row],[TRABAJADOR]], 'Colaborador ID'!B:C, 2, FALSE)) -> E0134 | C21: ALBERTO ENRIQUE MACIAS TEHERAN | D21: ES25 0182 9725 8102 0029 2530 | E21: BBVA | F21: #VALUE! | H21: #VALUE!
A22: 19 | B22: =IF(Tabla1[[#This Row],[TRABAJADOR]]="", "", VLOOKUP(Tabla1[[#This Row],[TRABAJADOR]], 'Colaborador ID'!B:C, 2, FALSE)) -> E0449 | C22: ALBERTO ISMAEL MENDIETA CACERES | D22: BE93 9052 9049 1967 | E22: WISE | F22: #VALUE! | G22: 46101 | H22: #VALUE!
A23: 20 | B23: =IF(Tabla1[[#This Row],[TRABAJADOR]]="", "", VLOOKUP(Tabla1[[#This Row],[TRABAJADOR]], 'Colaborador ID'!B:C, 2, FALSE)) -> E1448 | C23: ALBERTO LUIS MALDONADO BARRERA | D23: ES77 0182 0362 2502 0159 3681 | E23: BBVA | F23: #VALUE! | G23: 45953 | H23: #VALUE! | I23: STOCCO
A24: 21 | B24: =IF(Tabla1[[#This Row],[TRABAJADOR]]="", "", VLOOKUP(Tabla1[[#This Row],[TRABAJADOR]], 'Colaborador ID'!B:C, 2, FALSE)) -> E2142 | C24: ALBERTO RICHELLI DA SILVA | D24: PT50 0018 0003 5744 3293 0201 5 | E24: SANTANDER | F24: #VALUE! | G24: 46073 | H24: #VALUE!
A25: 22 | B25: =IF(Tabla1[[#This Row],[TRABAJADOR]]="", "", VLOOKUP(Tabla1[[#This Row],[TRABAJADOR]], 'Colaborador ID'!B:C, 2, FALSE)) -> E2114 | C25: ALDEMAR DOMINGUEZ CERCADO | D25: ES55 0182 1214 3302 0162 4902 | E25: BBVA | F25: #VALUE! | G25: 46073 | H25: #VALUE!
A26: 23 | B26: =IF(Tabla1[[#This Row],[TRABAJADOR]]="", "", VLOOKUP(Tabla1[[#This Row],[TRABAJADOR]], 'Colaborador ID'!B:C, 2, FALSE)) -> E0460 | C26: ALDO IVAN AILIO LABBE | D26: ES46 6893 0001 7400 0028 3429 | E26: NICKEL | F26: #VALUE! | G26: 45800 | H26: #VALUE!
A27: 24 | B27: =IF(Tabla1[[#This Row],[TRABAJADOR]]="", "", VLOOKUP(Tabla1[[#This Row],[TRABAJADOR]], 'Colaborador ID'!B:C, 2, FALSE)) -> E1382 | C27: ALDO LUIS CHACON BALAREZO | D27: ES06 0182 1250 4402 0157 8825 | E27: BBVA | F27: #VALUE! | H27: #VALUE!
A28: 25 | B28: =IF(Tabla1[[#This Row],[TRABAJADOR]]="", "", VLOOKUP(Tabla1[[#This Row],[TRABAJADOR]], 'Colaborador ID'!B:C, 2, FALSE)) -> E0648 | C28: ALDRUMAR CABALLERO MARTINEZ | D28: BE72 9054 0937 0016 | E28: WISE | F28: #VALUE! | G28: 45782 | H28: #VALUE!
A29: 26 | B29: =IF(Tabla1[[#This Row],[TRABAJADOR]]="", "", VLOOKUP(Tabla1[[#This Row],[TRABAJADOR]], 'Colaborador ID'!B:C, 2, FALSE)) -> E0243 | C29: ALEEX IVAN LOPEZ CUBILLOS | D29: ES40 6893 0001 7500 0023 4018 | F29: #VALUE! | H29: #VALUE!
A30: 27 | B30: =IF(Tabla1[[#This Row],[TRABAJADOR]]="", "", VLOOKUP(Tabla1[[#This Row],[TRABAJADOR]], 'Colaborador ID'!B:C, 2, FALSE)) -> E1770 | C30: ALEJANDRO ERWIN ZAMBRANO AGUILERA | D30: ES58 0049 5413 5422 1609 3588 | E30: SANTANDER | F30: #VALUE! | G30: 45894 | H30: #VALUE!
A31: 28 | B31: =IF(Tabla1[[#This Row],[TRABAJADOR]]="", "", VLOOKUP(Tabla1[[#This Row],[TRABAJADOR]], 'Colaborador ID'!B:C, 2, FALSE)) -> E0662 | C31: ALEJANDRO GONZALO URIBE | D31: PT50 0007 0000 0078 4116 1852 3 | F31: #VALUE! | H31: #VALUE!
A32: 29 | B32: =IF(Tabla1[[#This Row],[TRABAJADOR]]="", "", VLOOKUP(Tabla1[[#This Row],[TRABAJADOR]], 'Colaborador ID'!B:C, 2, FALSE)) -> E0009 | C32: ALEJANDRO HERNANDEZ PIMIENTA | D32: BE13 9053 6734 2239 | E32: WISE | F32: #VALUE! | G32: 45751 | H32: #VALUE!
A33: 30 | B33: =IF(Tabla1[[#This Row],[TRABAJADOR]]="", "", VLOOKUP(Tabla1[[#This Row],[TRABAJADOR]], 'Colaborador ID'!B:C, 2, FALSE)) -> E0128 | C33: ALEJANDRO JOSE BORJA MANGA | D33: ES69 0182 0043 1702 0168 0589 | F33: #VALUE! | H33: #VALUE!
A34: 31 | B34: =IF(Tabla1[[#This Row],[TRABAJADOR]]="", "", VLOOKUP(Tabla1[[#This Row],[TRABAJADOR]], 'Colaborador ID'!B:C, 2, FALSE)) -> E1253 | C34: ALESSANDRO SANTANA DE JESUS | D34: PT50 0033 0000 4558 3993 6640 5 | E34: MILLENNIUM | F34: #VALUE! | G34: 45761 | H34: #VALUE!
A35: 32 | B35: =IF(Tabla1[[#This Row],[TRABAJADOR]]="", "", VLOOKUP(Tabla1[[#This Row],[TRABAJADOR]], 'Colaborador ID'!B:C, 2, FALSE)) -> E1380 | C35: ALEX ALTAMAR CARMONA | D35: ES85 0182 8181 1502 0234 1275 | E35: BBVA | F35: #VALUE! | H35: #VALUE!
A36: 33 | B36: =IF(Tabla1[[#This Row],[TRABAJADOR]]="", "", VLOOKUP(Tabla1[[#This Row],[TRABAJADOR]], 'Colaborador ID'!B:C, 2, FALSE)) -> E0388 | C36: ALEX DAVID GOMEZ VILLADA | D36: ES71 0182 1270 9602 0166 8003 | E36: BBVA | F36: #VALUE! | H36: #VALUE!
A37: 34 | B37: =IF(Tabla1[[#This Row],[TRABAJADOR]]="", "", VLOOKUP(Tabla1[[#This Row],[TRABAJADOR]], 'Colaborador ID'!B:C, 2, FALSE)) -> E1921 | C37: ALEX JAVIER LEONEL OTAVO | D37: ES04 0182 2082 1502 0168 9129 | E37: BBVA | F37: #VALUE! | G37: 45944 | H37: #VALUE!
A38: 35 | B38: =IF(Tabla1[[#This Row],[TRABAJADOR]]="", "", VLOOKUP(Tabla1[[#This Row],[TRABAJADOR]], 'Colaborador ID'!B:C, 2, FALSE)) -> E1319 | C38: ALEX LUCAS SCHOROEDER | D38: PT50 0007 0000 0079 0352 4122 3 | E38: NOVOBANCO | F38: #VALUE! | H38: #VALUE!
A39: 36 | B39: =IF(Tabla1[[#This Row],[TRABAJADOR]]="", "", VLOOKUP(Tabla1[[#This Row],[TRABAJADOR]], 'Colaborador ID'!B:C, 2, FALSE)) -> E0593 | C39: ALEX MAURICIO CARDONA RAMIREZ | D39: ES86 0182 8181 1602 0234 6058 | E39: BBVA | F39: #VALUE! | G39: 45779 | H39: #VALUE!
A40: 37 | B40: =IF(Tabla1[[#This Row],[TRABAJADOR]]="", "", VLOOKUP(Tabla1[[#This Row],[TRABAJADOR]], 'Colaborador ID'!B:C, 2, FALSE)) -> E0302 | C40: ALEX MENDOZA ALCAZAR | D40: ES35 0182 5430 4702 0169 2651 | F40: #VALUE! | H40: #VALUE!
A41: 38 | B41: =IF(Tabla1[[#This Row],[TRABAJADOR]]="", "", VLOOKUP(Tabla1[[#This Row],[TRABAJADOR]], 'Colaborador ID'!B:C, 2, FALSE)) -> E1400 | C41: ALEXANDER ALONSO ROMERO | D41: ES45 0182 5400 2702 0221 8266 | E41: BBVA | F41: #VALUE! | G41: 45833 | H41: #VALUE!
A42: 39 | B42: =IF(Tabla1[[#This Row],[TRABAJADOR]]="", "", VLOOKUP(Tabla1[[#This Row],[TRABAJADOR]], 'Colaborador ID'!B:C, 2, FALSE)) -> E0362 | C42: ALEXANDER ANTHONY ZAMORA ALMENDARIZ | D42: ES58 6893 0001 7700 0027 5112 | E42: NICKEL | F42: #VALUE! | G42: 45751 | H42: #VALUE!
...

Sheet Colaborador ID
B1: Nombre | C1: Cod_colab
B2: ABDALLAH SAMMAR | C2: E1172
B3: ABDELFAHAM OUBOUZID | C3: E0530
B4: ABDELHAQ GUEHOUANE | C4: E1365
B5: ABDRUBAL FONSECA RINCON | C5: E1855
B6: ABEL ANTONIO CUESTA CIFUENTES | C6: E0663
B7: ABRAHAM DAVID HOYOS ALVAREZ | C7: E0513
B8: ADALBERTO ARAGON GOMEZ | C8: E0432
B9: ADILSON ESCOBAR OREJUELA | C9: E0687
B10: ADRIAN BERNAL GOMEZ | C10: E1050
B11: ADRIAN CAMILO PINILLA AGUIRRE | C11: E0570
B12: ADRIAN CARLOSAMA CHAVEZ | C12: E0452
... B1989: ZAIR GIL AMARIS | C1989: E1588
